[2021-09-06 04:13:20 +0000] [538] [INFO] Starting gunicorn 20.1.0
[2021-09-06 04:13:20 +0000] [538] [INFO] Listening at: http://0.0.0.0:8080 (538)
[2021-09-06 04:13:20 +0000] [538] [INFO] Using worker: sync
[2021-09-06 04:13:20 +0000] [548] [INFO] Booting worker with pid: 548
[2021-09-06 04:20:41 +0000] [548] [INFO] Worker exiting (pid: 548)
[2021-09-06 04:20:41 +0000] [538] [INFO] Handling signal: term
[2021-09-06 04:20:42 +0000] [538] [INFO] Shutting down: Master
[2021-09-06 04:20:45 +0000] [747] [INFO] Starting gunicorn 20.1.0
[2021-09-06 04:20:45 +0000] [747] [INFO] Listening at: http://0.0.0.0:8080 (747)
[2021-09-06 04:20:45 +0000] [747] [INFO] Using worker: sync
[2021-09-06 04:20:45 +0000] [757] [INFO] Booting worker with pid: 757
[2021-09-06 04:23:37 +0000] [757] [INFO] Worker exiting (pid: 757)
[2021-09-06 04:23:37 +0000] [747] [INFO] Handling signal: term
[2021-09-06 04:23:37 +0000] [747] [WARNING] Worker with pid 757 was terminated due to signal 15
[2021-09-06 04:23:37 +0000] [747] [INFO] Shutting down: Master
[2021-09-06 04:23:41 +0000] [806] [INFO] Starting gunicorn 20.1.0
[2021-09-06 04:23:41 +0000] [806] [INFO] Listening at: http://0.0.0.0:8080 (806)
[2021-09-06 04:23:41 +0000] [806] [INFO] Using worker: sync
[2021-09-06 04:23:41 +0000] [816] [INFO] Booting worker with pid: 816
[2021-09-06 04:48:22 +0000] [806] [INFO] Handling signal: winch
[2021-09-06 05:02:03 +0000] [806] [INFO] Handling signal: winch
[2021-09-06 05:50:45 +0000] [806] [INFO] Handling signal: winch
[2021-09-06 05:55:57 +0000] [806] [INFO] Handling signal: winch
[2021-09-06 05:57:26 +0000] [806] [INFO] Handling signal: term
[2021-09-06 05:57:26 +0000] [816] [INFO] Worker exiting (pid: 816)
[2021-09-06 05:57:26 +0000] [806] [INFO] Shutting down: Master
[2021-09-06 05:57:46 +0000] [971] [INFO] Starting gunicorn 20.1.0
[2021-09-06 05:57:46 +0000] [971] [INFO] Listening at: http://0.0.0.0:8080 (971)
[2021-09-06 05:57:46 +0000] [971] [INFO] Using worker: sync
[2021-09-06 05:57:46 +0000] [981] [INFO] Booting worker with pid: 981
[2021-09-06 06:01:58 +0000] [981] [INFO] Worker exiting (pid: 981)
[2021-09-06 06:01:58 +0000] [971] [INFO] Handling signal: term
[2021-09-06 06:01:58 +0000] [971] [INFO] Shutting down: Master
[2021-09-06 06:02:01 +0000] [1030] [INFO] Starting gunicorn 20.1.0
[2021-09-06 06:02:01 +0000] [1030] [INFO] Listening at: http://0.0.0.0:8080 (1030)
[2021-09-06 06:02:01 +0000] [1030] [INFO] Using worker: sync
[2021-09-06 06:02:01 +0000] [1037] [INFO] Booting worker with pid: 1037
[2021-09-06 06:55:11 +0000] [99] [INFO] Worker exiting (pid: 99)
[2021-09-06 06:55:18 +0000] [165] [INFO] Starting gunicorn 20.1.0
[2021-09-06 06:55:18 +0000] [165] [INFO] Listening at: http://0.0.0.0:8080 (165)
[2021-09-06 06:55:18 +0000] [165] [INFO] Using worker: sync
[2021-09-06 06:55:18 +0000] [175] [INFO] Booting worker with pid: 175
[2021-09-06 06:55:48 +0000] [175] [INFO] Worker exiting (pid: 175)
[2021-09-06 06:55:48 +0000] [165] [INFO] Handling signal: term
[2021-09-06 06:55:48 +0000] [165] [WARNING] Worker with pid 175 was terminated due to signal 15
[2021-09-06 06:55:48 +0000] [165] [INFO] Shutting down: Master
[2021-09-06 06:55:51 +0000] [201] [INFO] Starting gunicorn 20.1.0
[2021-09-06 06:55:51 +0000] [201] [INFO] Listening at: http://0.0.0.0:8080 (201)
[2021-09-06 06:55:51 +0000] [201] [INFO] Using worker: sync
[2021-09-06 06:55:51 +0000] [211] [INFO] Booting worker with pid: 211
[2021-09-06 07:00:16 +0000] [211] [INFO] Worker exiting (pid: 211)
[2021-09-06 07:00:16 +0000] [201] [INFO] Handling signal: term
[2021-09-06 07:00:16 +0000] [201] [WARNING] Worker with pid 211 was terminated due to signal 15
[2021-09-06 07:00:16 +0000] [201] [INFO] Shutting down: Master
[2021-09-06 07:00:26 +0000] [290] [INFO] Starting gunicorn 20.1.0
[2021-09-06 07:00:26 +0000] [290] [INFO] Listening at: http://0.0.0.0:8080 (290)
[2021-09-06 07:00:26 +0000] [290] [INFO] Using worker: sync
[2021-09-06 07:00:26 +0000] [297] [INFO] Booting worker with pid: 297
[2021-09-06 07:01:16 +0000] [297] [INFO] Worker exiting (pid: 297)
[2021-09-06 07:01:16 +0000] [290] [INFO] Handling signal: term
[2021-09-06 07:01:16 +0000] [290] [INFO] Shutting down: Master
[2021-09-06 07:01:19 +0000] [362] [INFO] Starting gunicorn 20.1.0
[2021-09-06 07:01:19 +0000] [362] [INFO] Listening at: http://0.0.0.0:8080 (362)
[2021-09-06 07:01:19 +0000] [362] [INFO] Using worker: sync
[2021-09-06 07:01:19 +0000] [372] [INFO] Booting worker with pid: 372
[2021-09-06 07:01:48 +0000] [362] [INFO] Handling signal: term
[2021-09-06 07:01:48 +0000] [372] [INFO] Worker exiting (pid: 372)
[2021-09-06 07:01:49 +0000] [362] [INFO] Shutting down: Master
[2021-09-06 07:01:50 +0000] [412] [INFO] Starting gunicorn 20.1.0
[2021-09-06 07:01:50 +0000] [412] [INFO] Listening at: http://0.0.0.0:8080 (412)
[2021-09-06 07:01:50 +0000] [412] [INFO] Using worker: sync
[2021-09-06 07:01:50 +0000] [422] [INFO] Booting worker with pid: 422
[2021-09-06 07:03:10 +0000] [422] [INFO] Worker exiting (pid: 422)
[2021-09-06 07:03:10 +0000] [412] [INFO] Handling signal: term
[2021-09-06 07:03:10 +0000] [412] [WARNING] Worker with pid 422 was terminated due to signal 15
[2021-09-06 07:03:10 +0000] [412] [INFO] Shutting down: Master
[2021-09-06 07:03:13 +0000] [479] [INFO] Starting gunicorn 20.1.0
[2021-09-06 07:03:13 +0000] [479] [INFO] Listening at: http://0.0.0.0:8080 (479)
[2021-09-06 07:03:13 +0000] [479] [INFO] Using worker: sync
[2021-09-06 07:03:13 +0000] [489] [INFO] Booting worker with pid: 489
[2021-09-06 07:03:37 +0000] [489] [INFO] Worker exiting (pid: 489)
[2021-09-06 07:03:37 +0000] [479] [INFO] Handling signal: term
[2021-09-06 07:03:37 +0000] [479] [INFO] Shutting down: Master
[2021-09-06 07:03:40 +0000] [514] [INFO] Starting gunicorn 20.1.0
[2021-09-06 07:03:40 +0000] [514] [INFO] Listening at: http://0.0.0.0:8080 (514)
[2021-09-06 07:03:40 +0000] [514] [INFO] Using worker: sync
[2021-09-06 07:03:40 +0000] [524] [INFO] Booting worker with pid: 524
[2021-09-06 07:03:41 +0000] [524] [ERROR] Exception in worker process
Traceback (most recent call last):
  File "/opt/virtualenvs/python3/lib/python3.8/site-packages/gunicorn/arbiter.py", line 589, in spawn_worker
    worker.init_process()
  File "/opt/virtualenvs/python3/lib/python3.8/site-packages/gunicorn/workers/base.py", line 134, in init_process
    self.load_wsgi()
  File "/opt/virtualenvs/python3/lib/python3.8/site-packages/gunicorn/workers/base.py", line 146, in load_wsgi
    self.wsgi = self.app.wsgi()
  File "/opt/virtualenvs/python3/lib/python3.8/site-packages/gunicorn/app/base.py", line 67, in wsgi
    self.callable = self.load()
  File "/opt/virtualenvs/python3/lib/python3.8/site-packages/gunicorn/app/wsgiapp.py", line 58, in load
    return self.load_wsgiapp()
  File "/opt/virtualenvs/python3/lib/python3.8/site-packages/gunicorn/app/wsgiapp.py", line 48, in load_wsgiapp
    return util.import_app(self.app_uri)
  File "/opt/virtualenvs/python3/lib/python3.8/site-packages/gunicorn/util.py", line 359, in import_app
    mod = importlib.import_module(module)
  File "/usr/lib/python3.8/importlib/__init__.py", line 127, in import_module
    return _bootstrap._gcd_import(name[level:], package, level)
  File "<frozen importlib._bootstrap>", line 1014, in _gcd_import
  File "<frozen importlib._bootstrap>", line 991, in _find_and_load
  File "<frozen importlib._bootstrap>", line 975, in _find_and_load_unlocked
  File "<frozen importlib._bootstrap>", line 671, in _load_unlocked
  File "<frozen importlib._bootstrap_external>", line 848, in exec_module
  File "<frozen importlib._bootstrap>", line 219, in _call_with_frames_removed
  File "/home/runner/wws/mysite/wsgi.py", line 8, in <module>
    application = WhiteNoise(application, root='/')
  File "/opt/virtualenvs/python3/lib/python3.8/site-packages/whitenoise/base.py", line 76, in __init__
    self.add_files(root, prefix)
  File "/opt/virtualenvs/python3/lib/python3.8/site-packages/whitenoise/base.py", line 113, in add_files
    self.update_files_dictionary(root, prefix)
  File "/opt/virtualenvs/python3/lib/python3.8/site-packages/whitenoise/base.py", line 120, in update_files_dictionary
    stat_cache = dict(scantree(root))
  File "/opt/virtualenvs/python3/lib/python3.8/site-packages/whitenoise/base.py", line 271, in scantree
    yield from scantree(entry.path)
  File "/opt/virtualenvs/python3/lib/python3.8/site-packages/whitenoise/base.py", line 269, in scantree
    for entry in os.scandir(root):
PermissionError: [Errno 13] Permission denied: '/root'
[2021-09-06 07:03:41 +0000] [524] [INFO] Worker exiting (pid: 524)
[2021-09-06 07:03:41 +0000] [514] [INFO] Shutting down: Master
[2021-09-06 07:03:41 +0000] [514] [INFO] Reason: Worker failed to boot.
[2021-09-06 07:03:46 +0000] [544] [INFO] Starting gunicorn 20.1.0
[2021-09-06 07:03:46 +0000] [544] [INFO] Listening at: http://0.0.0.0:8080 (544)
[2021-09-06 07:03:46 +0000] [544] [INFO] Using worker: sync
[2021-09-06 07:03:46 +0000] [554] [INFO] Booting worker with pid: 554
[2021-09-06 07:03:46 +0000] [554] [ERROR] Exception in worker process
Traceback (most recent call last):
  File "/opt/virtualenvs/python3/lib/python3.8/site-packages/gunicorn/arbiter.py", line 589, in spawn_worker
    worker.init_process()
  File "/opt/virtualenvs/python3/lib/python3.8/site-packages/gunicorn/workers/base.py", line 134, in init_process
    self.load_wsgi()
  File "/opt/virtualenvs/python3/lib/python3.8/site-packages/gunicorn/workers/base.py", line 146, in load_wsgi
    self.wsgi = self.app.wsgi()
  File "/opt/virtualenvs/python3/lib/python3.8/site-packages/gunicorn/app/base.py", line 67, in wsgi
    self.callable = self.load()
  File "/opt/virtualenvs/python3/lib/python3.8/site-packages/gunicorn/app/wsgiapp.py", line 58, in load
    return self.load_wsgiapp()
  File "/opt/virtualenvs/python3/lib/python3.8/site-packages/gunicorn/app/wsgiapp.py", line 48, in load_wsgiapp
    return util.import_app(self.app_uri)
  File "/opt/virtualenvs/python3/lib/python3.8/site-packages/gunicorn/util.py", line 359, in import_app
    mod = importlib.import_module(module)
  File "/usr/lib/python3.8/importlib/__init__.py", line 127, in import_module
    return _bootstrap._gcd_import(name[level:], package, level)
  File "<frozen importlib._bootstrap>", line 1014, in _gcd_import
  File "<frozen importlib._bootstrap>", line 991, in _find_and_load
  File "<frozen importlib._bootstrap>", line 975, in _find_and_load_unlocked
  File "<frozen importlib._bootstrap>", line 671, in _load_unlocked
  File "<frozen importlib._bootstrap_external>", line 848, in exec_module
  File "<frozen importlib._bootstrap>", line 219, in _call_with_frames_removed
  File "/home/runner/wws/mysite/wsgi.py", line 8, in <module>
    application = WhiteNoise(application, root='/')
  File "/opt/virtualenvs/python3/lib/python3.8/site-packages/whitenoise/base.py", line 76, in __init__
    self.add_files(root, prefix)
  File "/opt/virtualenvs/python3/lib/python3.8/site-packages/whitenoise/base.py", line 113, in add_files
    self.update_files_dictionary(root, prefix)
  File "/opt/virtualenvs/python3/lib/python3.8/site-packages/whitenoise/base.py", line 120, in update_files_dictionary
    stat_cache = dict(scantree(root))
  File "/opt/virtualenvs/python3/lib/python3.8/site-packages/whitenoise/base.py", line 271, in scantree
    yield from scantree(entry.path)
  File "/opt/virtualenvs/python3/lib/python3.8/site-packages/whitenoise/base.py", line 269, in scantree
    for entry in os.scandir(root):
PermissionError: [Errno 13] Permission denied: '/root'
[2021-09-06 07:03:46 +0000] [554] [INFO] Worker exiting (pid: 554)
[2021-09-06 07:03:47 +0000] [544] [INFO] Shutting down: Master
[2021-09-06 07:03:47 +0000] [544] [INFO] Reason: Worker failed to boot.
[2021-09-06 07:03:51 +0000] [574] [INFO] Starting gunicorn 20.1.0
[2021-09-06 07:03:51 +0000] [574] [INFO] Listening at: http://0.0.0.0:8080 (574)
[2021-09-06 07:03:51 +0000] [574] [INFO] Using worker: sync
[2021-09-06 07:03:51 +0000] [584] [INFO] Booting worker with pid: 584
[2021-09-06 07:03:52 +0000] [584] [ERROR] Exception in worker process
Traceback (most recent call last):
  File "/opt/virtualenvs/python3/lib/python3.8/site-packages/gunicorn/arbiter.py", line 589, in spawn_worker
    worker.init_process()
  File "/opt/virtualenvs/python3/lib/python3.8/site-packages/gunicorn/workers/base.py", line 134, in init_process
    self.load_wsgi()
  File "/opt/virtualenvs/python3/lib/python3.8/site-packages/gunicorn/workers/base.py", line 146, in load_wsgi
    self.wsgi = self.app.wsgi()
  File "/opt/virtualenvs/python3/lib/python3.8/site-packages/gunicorn/app/base.py", line 67, in wsgi
    self.callable = self.load()
  File "/opt/virtualenvs/python3/lib/python3.8/site-packages/gunicorn/app/wsgiapp.py", line 58, in load
    return self.load_wsgiapp()
  File "/opt/virtualenvs/python3/lib/python3.8/site-packages/gunicorn/app/wsgiapp.py", line 48, in load_wsgiapp
    return util.import_app(self.app_uri)
  File "/opt/virtualenvs/python3/lib/python3.8/site-packages/gunicorn/util.py", line 359, in import_app
    mod = importlib.import_module(module)
  File "/usr/lib/python3.8/importlib/__init__.py", line 127, in import_module
    return _bootstrap._gcd_import(name[level:], package, level)
  File "<frozen importlib._bootstrap>", line 1014, in _gcd_import
  File "<frozen importlib._bootstrap>", line 991, in _find_and_load
  File "<frozen importlib._bootstrap>", line 975, in _find_and_load_unlocked
  File "<frozen importlib._bootstrap>", line 671, in _load_unlocked
  File "<frozen importlib._bootstrap_external>", line 848, in exec_module
  File "<frozen importlib._bootstrap>", line 219, in _call_with_frames_removed
  File "/home/runner/wws/mysite/wsgi.py", line 8, in <module>
    application = WhiteNoise(application, root='/')
  File "/opt/virtualenvs/python3/lib/python3.8/site-packages/whitenoise/base.py", line 76, in __init__
    self.add_files(root, prefix)
  File "/opt/virtualenvs/python3/lib/python3.8/site-packages/whitenoise/base.py", line 113, in add_files
    self.update_files_dictionary(root, prefix)
  File "/opt/virtualenvs/python3/lib/python3.8/site-packages/whitenoise/base.py", line 120, in update_files_dictionary
    stat_cache = dict(scantree(root))
  File "/opt/virtualenvs/python3/lib/python3.8/site-packages/whitenoise/base.py", line 271, in scantree
    yield from scantree(entry.path)
  File "/opt/virtualenvs/python3/lib/python3.8/site-packages/whitenoise/base.py", line 269, in scantree
    for entry in os.scandir(root):
PermissionError: [Errno 13] Permission denied: '/root'
[2021-09-06 07:03:52 +0000] [584] [INFO] Worker exiting (pid: 584)
[2021-09-06 07:03:53 +0000] [574] [INFO] Shutting down: Master
[2021-09-06 07:03:53 +0000] [574] [INFO] Reason: Worker failed to boot.
[2021-09-06 07:04:07 +0000] [605] [INFO] Starting gunicorn 20.1.0
[2021-09-06 07:04:07 +0000] [605] [INFO] Listening at: http://0.0.0.0:8080 (605)
[2021-09-06 07:04:07 +0000] [605] [INFO] Using worker: sync
[2021-09-06 07:04:07 +0000] [615] [INFO] Booting worker with pid: 615
[2021-09-06 07:04:18 +0000] [615] [INFO] Worker exiting (pid: 615)
[2021-09-06 07:04:18 +0000] [605] [INFO] Handling signal: term
[2021-09-06 07:04:18 +0000] [605] [WARNING] Worker with pid 615 was terminated due to signal 15
[2021-09-06 07:04:18 +0000] [605] [INFO] Shutting down: Master
[2021-09-06 07:04:22 +0000] [670] [INFO] Starting gunicorn 20.1.0
[2021-09-06 07:04:22 +0000] [670] [INFO] Listening at: http://0.0.0.0:8080 (670)
[2021-09-06 07:04:22 +0000] [670] [INFO] Using worker: sync
[2021-09-06 07:04:22 +0000] [680] [INFO] Booting worker with pid: 680
[2021-09-06 07:07:16 +0000] [680] [INFO] Worker exiting (pid: 680)
[2021-09-06 07:07:16 +0000] [670] [INFO] Handling signal: term
[2021-09-06 07:07:16 +0000] [670] [INFO] Shutting down: Master
[2021-09-06 07:07:19 +0000] [703] [INFO] Starting gunicorn 20.1.0
[2021-09-06 07:07:19 +0000] [703] [INFO] Listening at: http://0.0.0.0:8080 (703)
[2021-09-06 07:07:19 +0000] [703] [INFO] Using worker: sync
[2021-09-06 07:07:19 +0000] [713] [INFO] Booting worker with pid: 713
[2021-09-06 07:07:45 +0000] [713] [INFO] Worker exiting (pid: 713)
[2021-09-06 07:07:45 +0000] [703] [INFO] Handling signal: term
[2021-09-06 07:07:45 +0000] [703] [WARNING] Worker with pid 713 was terminated due to signal 15
[2021-09-06 07:07:45 +0000] [703] [INFO] Shutting down: Master
[2021-09-06 07:08:03 +0000] [741] [INFO] Starting gunicorn 20.1.0
[2021-09-06 07:08:03 +0000] [741] [INFO] Listening at: http://0.0.0.0:8080 (741)
[2021-09-06 07:08:03 +0000] [741] [INFO] Using worker: sync
[2021-09-06 07:08:03 +0000] [751] [INFO] Booting worker with pid: 751
[2021-09-06 07:08:21 +0000] [751] [INFO] Worker exiting (pid: 751)
[2021-09-06 07:08:21 +0000] [741] [INFO] Handling signal: term
[2021-09-06 07:08:22 +0000] [741] [INFO] Shutting down: Master
[2021-09-06 07:08:24 +0000] [771] [INFO] Starting gunicorn 20.1.0
[2021-09-06 07:08:24 +0000] [771] [INFO] Listening at: http://0.0.0.0:8080 (771)
[2021-09-06 07:08:24 +0000] [771] [INFO] Using worker: sync
[2021-09-06 07:08:24 +0000] [781] [INFO] Booting worker with pid: 781
[2021-09-06 07:09:00 +0000] [781] [INFO] Worker exiting (pid: 781)
[2021-09-06 07:09:00 +0000] [771] [INFO] Handling signal: term
[2021-09-06 07:09:01 +0000] [771] [INFO] Shutting down: Master
[2021-09-06 07:09:03 +0000] [801] [INFO] Starting gunicorn 20.1.0
[2021-09-06 07:09:03 +0000] [801] [INFO] Listening at: http://0.0.0.0:8080 (801)
[2021-09-06 07:09:03 +0000] [801] [INFO] Using worker: sync
[2021-09-06 07:09:03 +0000] [809] [INFO] Booting worker with pid: 809
[2021-09-06 07:09:59 +0000] [809] [INFO] Worker exiting (pid: 809)
[2021-09-06 07:09:59 +0000] [801] [INFO] Handling signal: term
[2021-09-06 07:09:59 +0000] [801] [WARNING] Worker with pid 809 was terminated due to signal 15
[2021-09-06 07:09:59 +0000] [801] [INFO] Shutting down: Master
[2021-09-06 07:10:02 +0000] [838] [INFO] Starting gunicorn 20.1.0
[2021-09-06 07:10:02 +0000] [838] [INFO] Listening at: http://0.0.0.0:8080 (838)
[2021-09-06 07:10:02 +0000] [838] [INFO] Using worker: sync
[2021-09-06 07:10:02 +0000] [848] [INFO] Booting worker with pid: 848
[2021-09-06 07:12:17 +0000] [848] [INFO] Worker exiting (pid: 848)
[2021-09-06 07:12:17 +0000] [838] [INFO] Handling signal: term
[2021-09-06 07:12:17 +0000] [838] [INFO] Shutting down: Master
[2021-09-06 07:12:29 +0000] [868] [INFO] Starting gunicorn 20.1.0
[2021-09-06 07:12:29 +0000] [868] [INFO] Listening at: http://0.0.0.0:8080 (868)
[2021-09-06 07:12:29 +0000] [868] [INFO] Using worker: sync
[2021-09-06 07:12:29 +0000] [878] [INFO] Booting worker with pid: 878
[2021-09-06 07:13:10 +0000] [878] [INFO] Worker exiting (pid: 878)
[2021-09-06 07:13:10 +0000] [868] [INFO] Handling signal: term
[2021-09-06 07:13:10 +0000] [868] [INFO] Shutting down: Master
[2021-09-06 07:13:13 +0000] [906] [INFO] Starting gunicorn 20.1.0
[2021-09-06 07:13:13 +0000] [906] [INFO] Listening at: http://0.0.0.0:8080 (906)
[2021-09-06 07:13:13 +0000] [906] [INFO] Using worker: sync
[2021-09-06 07:13:13 +0000] [916] [INFO] Booting worker with pid: 916
[2021-09-06 07:13:41 +0000] [916] [INFO] Worker exiting (pid: 916)
[2021-09-06 07:13:41 +0000] [906] [INFO] Handling signal: term
[2021-09-06 07:13:41 +0000] [906] [INFO] Shutting down: Master
[2021-09-06 07:13:44 +0000] [942] [INFO] Starting gunicorn 20.1.0
[2021-09-06 07:13:44 +0000] [942] [INFO] Listening at: http://0.0.0.0:8080 (942)
[2021-09-06 07:13:44 +0000] [942] [INFO] Using worker: sync
[2021-09-06 07:13:44 +0000] [952] [INFO] Booting worker with pid: 952
[2021-09-06 07:13:59 +0000] [952] [INFO] Worker exiting (pid: 952)
[2021-09-06 07:13:59 +0000] [942] [INFO] Handling signal: term
[2021-09-06 07:14:00 +0000] [942] [INFO] Shutting down: Master
[2021-09-06 07:14:11 +0000] [972] [INFO] Starting gunicorn 20.1.0
[2021-09-06 07:14:11 +0000] [972] [INFO] Listening at: http://0.0.0.0:8080 (972)
[2021-09-06 07:14:11 +0000] [972] [INFO] Using worker: sync
[2021-09-06 07:14:11 +0000] [982] [INFO] Booting worker with pid: 982
[2021-09-06 07:16:01 +0000] [982] [INFO] Worker exiting (pid: 982)
[2021-09-06 07:16:01 +0000] [972] [INFO] Handling signal: term
[2021-09-06 07:16:01 +0000] [972] [WARNING] Worker with pid 982 was terminated due to signal 15
[2021-09-06 07:16:01 +0000] [972] [INFO] Shutting down: Master
[2021-09-06 07:16:04 +0000] [1000] [INFO] Starting gunicorn 20.1.0
[2021-09-06 07:16:04 +0000] [1000] [INFO] Listening at: http://0.0.0.0:8080 (1000)
[2021-09-06 07:16:04 +0000] [1000] [INFO] Using worker: sync
[2021-09-06 07:16:04 +0000] [1010] [INFO] Booting worker with pid: 1010
[2021-09-06 07:17:16 +0000] [1010] [INFO] Worker exiting (pid: 1010)
[2021-09-06 07:17:16 +0000] [1000] [INFO] Handling signal: term
[2021-09-06 07:17:16 +0000] [1000] [INFO] Shutting down: Master
[2021-09-06 07:17:19 +0000] [1029] [INFO] Starting gunicorn 20.1.0
[2021-09-06 07:17:19 +0000] [1029] [INFO] Listening at: http://0.0.0.0:8080 (1029)
[2021-09-06 07:17:19 +0000] [1029] [INFO] Using worker: sync
[2021-09-06 07:17:19 +0000] [1039] [INFO] Booting worker with pid: 1039
[2021-09-06 07:18:13 +0000] [1039] [INFO] Worker exiting (pid: 1039)
[2021-09-06 07:18:13 +0000] [1029] [INFO] Handling signal: term
[2021-09-06 07:18:13 +0000] [1029] [INFO] Shutting down: Master
[2021-09-06 07:18:16 +0000] [1065] [INFO] Starting gunicorn 20.1.0
[2021-09-06 07:18:16 +0000] [1065] [INFO] Listening at: http://0.0.0.0:8080 (1065)
[2021-09-06 07:18:16 +0000] [1065] [INFO] Using worker: sync
[2021-09-06 07:18:16 +0000] [1075] [INFO] Booting worker with pid: 1075
[2021-09-06 07:18:56 +0000] [1075] [INFO] Worker exiting (pid: 1075)
[2021-09-06 07:18:56 +0000] [1065] [INFO] Handling signal: term
[2021-09-06 07:18:56 +0000] [1065] [WARNING] Worker with pid 1075 was terminated due to signal 15
[2021-09-06 07:18:56 +0000] [1065] [INFO] Shutting down: Master
[2021-09-06 07:18:59 +0000] [1095] [INFO] Starting gunicorn 20.1.0
[2021-09-06 07:18:59 +0000] [1095] [INFO] Listening at: http://0.0.0.0:8080 (1095)
[2021-09-06 07:18:59 +0000] [1095] [INFO] Using worker: sync
[2021-09-06 07:18:59 +0000] [1105] [INFO] Booting worker with pid: 1105
[2021-09-06 07:19:15 +0000] [1095] [INFO] Handling signal: term
[2021-09-06 07:19:15 +0000] [1105] [INFO] Worker exiting (pid: 1105)
[2021-09-06 07:19:16 +0000] [1095] [INFO] Shutting down: Master
[2021-09-06 07:19:21 +0000] [1143] [INFO] Starting gunicorn 20.1.0
[2021-09-06 07:19:21 +0000] [1143] [INFO] Listening at: http://0.0.0.0:8080 (1143)
[2021-09-06 07:19:21 +0000] [1143] [INFO] Using worker: sync
[2021-09-06 07:19:21 +0000] [1153] [INFO] Booting worker with pid: 1153
[2021-09-06 07:21:07 +0000] [1143] [INFO] Handling signal: term
[2021-09-06 07:21:07 +0000] [1153] [INFO] Worker exiting (pid: 1153)
[2021-09-06 07:21:07 +0000] [1143] [INFO] Shutting down: Master
[2021-09-06 07:21:10 +0000] [1173] [INFO] Starting gunicorn 20.1.0
[2021-09-06 07:21:10 +0000] [1173] [INFO] Listening at: http://0.0.0.0:8080 (1173)
[2021-09-06 07:21:10 +0000] [1173] [INFO] Using worker: sync
[2021-09-06 07:21:10 +0000] [1183] [INFO] Booting worker with pid: 1183
[2021-09-06 07:21:23 +0000] [1183] [INFO] Worker exiting (pid: 1183)
[2021-09-06 07:21:23 +0000] [1173] [INFO] Handling signal: term
[2021-09-06 07:21:23 +0000] [1173] [INFO] Shutting down: Master
[2021-09-06 07:21:26 +0000] [1202] [INFO] Starting gunicorn 20.1.0
[2021-09-06 07:21:26 +0000] [1202] [INFO] Listening at: http://0.0.0.0:8080 (1202)
[2021-09-06 07:21:26 +0000] [1202] [INFO] Using worker: sync
[2021-09-06 07:21:26 +0000] [1212] [INFO] Booting worker with pid: 1212
[2021-09-06 07:22:01 +0000] [1202] [INFO] Handling signal: term
[2021-09-06 07:22:01 +0000] [1212] [INFO] Worker exiting (pid: 1212)
[2021-09-06 07:22:01 +0000] [1202] [WARNING] Worker with pid 1212 was terminated due to signal 15
[2021-09-06 07:22:01 +0000] [1202] [INFO] Shutting down: Master
[2021-09-06 07:22:07 +0000] [1276] [INFO] Starting gunicorn 20.1.0
[2021-09-06 07:22:07 +0000] [1276] [INFO] Listening at: http://0.0.0.0:8080 (1276)
[2021-09-06 07:22:07 +0000] [1276] [INFO] Using worker: sync
[2021-09-06 07:22:07 +0000] [1286] [INFO] Booting worker with pid: 1286
[2021-09-06 07:22:44 +0000] [1286] [INFO] Worker exiting (pid: 1286)
[2021-09-06 07:22:44 +0000] [1276] [INFO] Handling signal: term
[2021-09-06 07:22:44 +0000] [1276] [WARNING] Worker with pid 1286 was terminated due to signal 15
[2021-09-06 07:22:44 +0000] [1276] [INFO] Shutting down: Master
[2021-09-06 07:22:46 +0000] [1304] [INFO] Starting gunicorn 20.1.0
[2021-09-06 07:22:46 +0000] [1304] [INFO] Listening at: http://0.0.0.0:8080 (1304)
[2021-09-06 07:22:46 +0000] [1304] [INFO] Using worker: sync
[2021-09-06 07:22:46 +0000] [1314] [INFO] Booting worker with pid: 1314
[2021-09-06 07:23:02 +0000] [1314] [INFO] Worker exiting (pid: 1314)
[2021-09-06 07:23:02 +0000] [1304] [INFO] Handling signal: term
[2021-09-06 07:23:02 +0000] [1304] [INFO] Shutting down: Master
[2021-09-06 07:23:03 +0000] [1341] [INFO] Starting gunicorn 20.1.0
[2021-09-06 07:23:03 +0000] [1341] [INFO] Listening at: http://0.0.0.0:8080 (1341)
[2021-09-06 07:23:03 +0000] [1341] [INFO] Using worker: sync
[2021-09-06 07:23:03 +0000] [1351] [INFO] Booting worker with pid: 1351
[2021-09-06 07:25:05 +0000] [1351] [INFO] Worker exiting (pid: 1351)
[2021-09-06 07:25:05 +0000] [1341] [INFO] Handling signal: term
[2021-09-06 07:25:06 +0000] [1341] [INFO] Shutting down: Master
[2021-09-06 07:25:09 +0000] [1370] [INFO] Starting gunicorn 20.1.0
[2021-09-06 07:25:09 +0000] [1370] [INFO] Listening at: http://0.0.0.0:8080 (1370)
[2021-09-06 07:25:09 +0000] [1370] [INFO] Using worker: sync
[2021-09-06 07:25:09 +0000] [1380] [INFO] Booting worker with pid: 1380
[2021-09-06 07:25:59 +0000] [1380] [INFO] Worker exiting (pid: 1380)
[2021-09-06 07:25:59 +0000] [1370] [INFO] Handling signal: term
[2021-09-06 07:25:59 +0000] [1370] [WARNING] Worker with pid 1380 was terminated due to signal 15
[2021-09-06 07:25:59 +0000] [1370] [INFO] Shutting down: Master
[2021-09-06 07:26:00 +0000] [1400] [INFO] Starting gunicorn 20.1.0
[2021-09-06 07:26:00 +0000] [1400] [INFO] Listening at: http://0.0.0.0:8080 (1400)
[2021-09-06 07:26:00 +0000] [1400] [INFO] Using worker: sync
[2021-09-06 07:26:00 +0000] [1410] [INFO] Booting worker with pid: 1410
[2021-09-06 07:26:25 +0000] [1400] [INFO] Handling signal: winch
[2021-09-06 07:26:25 +0000] [1400] [INFO] Handling signal: winch
[2021-09-06 07:27:04 +0000] [1400] [INFO] Handling signal: term
[2021-09-06 07:27:04 +0000] [1410] [INFO] Worker exiting (pid: 1410)
[2021-09-06 07:27:04 +0000] [1400] [INFO] Shutting down: Master
[2021-09-06 07:27:07 +0000] [1445] [INFO] Starting gunicorn 20.1.0
[2021-09-06 07:27:07 +0000] [1445] [INFO] Listening at: http://0.0.0.0:8080 (1445)
[2021-09-06 07:27:07 +0000] [1445] [INFO] Using worker: sync
[2021-09-06 07:27:07 +0000] [1455] [INFO] Booting worker with pid: 1455
[2021-09-06 07:27:48 +0000] [1455] [INFO] Worker exiting (pid: 1455)
[2021-09-06 07:27:48 +0000] [1445] [INFO] Handling signal: term
[2021-09-06 07:27:48 +0000] [1445] [INFO] Shutting down: Master
[2021-09-06 07:27:51 +0000] [1481] [INFO] Starting gunicorn 20.1.0
[2021-09-06 07:27:51 +0000] [1481] [INFO] Listening at: http://0.0.0.0:8080 (1481)
[2021-09-06 07:27:51 +0000] [1481] [INFO] Using worker: sync
[2021-09-06 07:27:51 +0000] [1491] [INFO] Booting worker with pid: 1491
[2021-09-06 07:28:07 +0000] [1481] [INFO] Handling signal: term
[2021-09-06 07:28:07 +0000] [1491] [INFO] Worker exiting (pid: 1491)
[2021-09-06 07:28:08 +0000] [1481] [INFO] Shutting down: Master
[2021-09-06 07:28:09 +0000] [1511] [INFO] Starting gunicorn 20.1.0
[2021-09-06 07:28:09 +0000] [1511] [INFO] Listening at: http://0.0.0.0:8080 (1511)
[2021-09-06 07:28:09 +0000] [1511] [INFO] Using worker: sync
[2021-09-06 07:28:09 +0000] [1521] [INFO] Booting worker with pid: 1521
[2021-09-06 07:28:37 +0000] [1521] [INFO] Worker exiting (pid: 1521)
[2021-09-06 07:28:37 +0000] [1511] [INFO] Handling signal: term
[2021-09-06 07:28:37 +0000] [1511] [WARNING] Worker with pid 1521 was terminated due to signal 15
[2021-09-06 07:28:37 +0000] [1511] [INFO] Shutting down: Master
[2021-09-06 07:28:39 +0000] [1541] [INFO] Starting gunicorn 20.1.0
[2021-09-06 07:28:39 +0000] [1541] [INFO] Listening at: http://0.0.0.0:8080 (1541)
[2021-09-06 07:28:39 +0000] [1541] [INFO] Using worker: sync
[2021-09-06 07:28:39 +0000] [1551] [INFO] Booting worker with pid: 1551
[2021-09-06 07:29:10 +0000] [1551] [INFO] Worker exiting (pid: 1551)
[2021-09-06 07:29:10 +0000] [1541] [INFO] Handling signal: term
[2021-09-06 07:29:10 +0000] [1541] [WARNING] Worker with pid 1551 was terminated due to signal 15
[2021-09-06 07:29:10 +0000] [1541] [INFO] Shutting down: Master
[2021-09-06 07:29:11 +0000] [1569] [INFO] Starting gunicorn 20.1.0
[2021-09-06 07:29:11 +0000] [1569] [INFO] Listening at: http://0.0.0.0:8080 (1569)
[2021-09-06 07:29:11 +0000] [1569] [INFO] Using worker: sync
[2021-09-06 07:29:11 +0000] [1576] [INFO] Booting worker with pid: 1576
[2021-09-06 07:29:36 +0000] [1576] [INFO] Worker exiting (pid: 1576)
[2021-09-06 07:29:36 +0000] [1569] [INFO] Handling signal: term
[2021-09-06 07:29:36 +0000] [1569] [INFO] Shutting down: Master
[2021-09-06 07:29:37 +0000] [1599] [INFO] Starting gunicorn 20.1.0
[2021-09-06 07:29:37 +0000] [1599] [INFO] Listening at: http://0.0.0.0:8080 (1599)
[2021-09-06 07:29:37 +0000] [1599] [INFO] Using worker: sync
[2021-09-06 07:29:37 +0000] [1609] [INFO] Booting worker with pid: 1609
[2021-09-06 07:30:23 +0000] [1609] [INFO] Worker exiting (pid: 1609)
[2021-09-06 07:30:23 +0000] [1599] [INFO] Handling signal: term
[2021-09-06 07:30:23 +0000] [1599] [WARNING] Worker with pid 1609 was terminated due to signal 15
[2021-09-06 07:30:24 +0000] [1599] [INFO] Shutting down: Master
[2021-09-06 07:30:25 +0000] [1629] [INFO] Starting gunicorn 20.1.0
[2021-09-06 07:30:25 +0000] [1629] [INFO] Listening at: http://0.0.0.0:8080 (1629)
[2021-09-06 07:30:25 +0000] [1629] [INFO] Using worker: sync
[2021-09-06 07:30:25 +0000] [1639] [INFO] Booting worker with pid: 1639
[2021-09-06 07:30:52 +0000] [1639] [INFO] Worker exiting (pid: 1639)
[2021-09-06 07:30:52 +0000] [1629] [INFO] Handling signal: term
[2021-09-06 07:30:53 +0000] [1629] [INFO] Shutting down: Master
[2021-09-06 07:30:54 +0000] [1659] [INFO] Starting gunicorn 20.1.0
[2021-09-06 07:30:54 +0000] [1659] [INFO] Listening at: http://0.0.0.0:8080 (1659)
[2021-09-06 07:30:54 +0000] [1659] [INFO] Using worker: sync
[2021-09-06 07:30:54 +0000] [1669] [INFO] Booting worker with pid: 1669
[2021-09-06 07:31:08 +0000] [1669] [INFO] Worker exiting (pid: 1669)
[2021-09-06 07:31:08 +0000] [1659] [INFO] Handling signal: term
[2021-09-06 07:31:08 +0000] [1659] [WARNING] Worker with pid 1669 was terminated due to signal 15
[2021-09-06 07:31:08 +0000] [1659] [INFO] Shutting down: Master
[2021-09-06 07:31:09 +0000] [1689] [INFO] Starting gunicorn 20.1.0
[2021-09-06 07:31:09 +0000] [1689] [INFO] Listening at: http://0.0.0.0:8080 (1689)
[2021-09-06 07:31:09 +0000] [1689] [INFO] Using worker: sync
[2021-09-06 07:31:09 +0000] [1699] [INFO] Booting worker with pid: 1699
[2021-09-06 07:31:21 +0000] [1699] [INFO] Worker exiting (pid: 1699)
[2021-09-06 07:31:21 +0000] [1689] [INFO] Handling signal: term
[2021-09-06 07:31:21 +0000] [1689] [INFO] Shutting down: Master
[2021-09-06 07:31:22 +0000] [1719] [INFO] Starting gunicorn 20.1.0
[2021-09-06 07:31:22 +0000] [1719] [INFO] Listening at: http://0.0.0.0:8080 (1719)
[2021-09-06 07:31:22 +0000] [1719] [INFO] Using worker: sync
[2021-09-06 07:31:22 +0000] [1729] [INFO] Booting worker with pid: 1729
[2021-09-06 07:31:33 +0000] [1729] [INFO] Worker exiting (pid: 1729)
[2021-09-06 07:31:33 +0000] [1719] [INFO] Handling signal: term
[2021-09-06 07:31:33 +0000] [1719] [INFO] Shutting down: Master
[2021-09-06 07:31:34 +0000] [1757] [INFO] Starting gunicorn 20.1.0
[2021-09-06 07:31:34 +0000] [1757] [INFO] Listening at: http://0.0.0.0:8080 (1757)
[2021-09-06 07:31:34 +0000] [1757] [INFO] Using worker: sync
[2021-09-06 07:31:34 +0000] [1767] [INFO] Booting worker with pid: 1767
[2021-09-06 07:31:47 +0000] [1767] [INFO] Worker exiting (pid: 1767)
[2021-09-06 07:31:47 +0000] [1757] [INFO] Handling signal: term
[2021-09-06 07:31:47 +0000] [1757] [INFO] Shutting down: Master
[2021-09-06 07:31:48 +0000] [1786] [INFO] Starting gunicorn 20.1.0
[2021-09-06 07:31:48 +0000] [1786] [INFO] Listening at: http://0.0.0.0:8080 (1786)
[2021-09-06 07:31:48 +0000] [1786] [INFO] Using worker: sync
[2021-09-06 07:31:48 +0000] [1794] [INFO] Booting worker with pid: 1794
[2021-09-06 07:33:57 +0000] [1794] [INFO] Worker exiting (pid: 1794)
[2021-09-06 07:33:57 +0000] [1786] [INFO] Handling signal: term
[2021-09-06 07:33:58 +0000] [1786] [INFO] Shutting down: Master
[2021-09-06 07:33:59 +0000] [1816] [INFO] Starting gunicorn 20.1.0
[2021-09-06 07:33:59 +0000] [1816] [INFO] Listening at: http://0.0.0.0:8080 (1816)
[2021-09-06 07:33:59 +0000] [1816] [INFO] Using worker: sync
[2021-09-06 07:33:59 +0000] [1826] [INFO] Booting worker with pid: 1826
[2021-09-06 07:35:53 +0000] [1826] [INFO] Worker exiting (pid: 1826)
[2021-09-06 07:35:53 +0000] [1816] [INFO] Handling signal: term
[2021-09-06 07:35:54 +0000] [1816] [INFO] Shutting down: Master
[2021-09-06 07:35:55 +0000] [1845] [INFO] Starting gunicorn 20.1.0
[2021-09-06 07:35:55 +0000] [1845] [INFO] Listening at: http://0.0.0.0:8080 (1845)
[2021-09-06 07:35:55 +0000] [1845] [INFO] Using worker: sync
[2021-09-06 07:35:55 +0000] [1855] [INFO] Booting worker with pid: 1855
[2021-09-06 07:37:34 +0000] [1845] [INFO] Handling signal: term
[2021-09-06 07:37:34 +0000] [1855] [INFO] Worker exiting (pid: 1855)
[2021-09-06 07:37:34 +0000] [1845] [INFO] Shutting down: Master
[2021-09-06 07:37:35 +0000] [1883] [INFO] Starting gunicorn 20.1.0
[2021-09-06 07:37:35 +0000] [1883] [INFO] Listening at: http://0.0.0.0:8080 (1883)
[2021-09-06 07:37:35 +0000] [1883] [INFO] Using worker: sync
[2021-09-06 07:37:35 +0000] [1893] [INFO] Booting worker with pid: 1893
[2021-09-06 07:38:49 +0000] [1893] [INFO] Worker exiting (pid: 1893)
[2021-09-06 07:38:49 +0000] [1883] [INFO] Handling signal: term
[2021-09-06 07:38:49 +0000] [1883] [INFO] Shutting down: Master
[2021-09-06 07:38:50 +0000] [1913] [INFO] Starting gunicorn 20.1.0
[2021-09-06 07:38:50 +0000] [1913] [INFO] Listening at: http://0.0.0.0:8080 (1913)
[2021-09-06 07:38:50 +0000] [1913] [INFO] Using worker: sync
[2021-09-06 07:38:50 +0000] [1920] [INFO] Booting worker with pid: 1920
[2021-09-06 07:41:55 +0000] [1913] [INFO] Handling signal: winch
[2021-09-06 07:42:16 +0000] [1913] [INFO] Handling signal: term
[2021-09-06 07:42:16 +0000] [1920] [INFO] Worker exiting (pid: 1920)
[2021-09-06 07:42:16 +0000] [1913] [INFO] Shutting down: Master
[2021-09-06 07:42:17 +0000] [1965] [INFO] Starting gunicorn 20.1.0
[2021-09-06 07:42:17 +0000] [1965] [INFO] Listening at: http://0.0.0.0:8080 (1965)
[2021-09-06 07:42:17 +0000] [1965] [INFO] Using worker: sync
[2021-09-06 07:42:17 +0000] [1975] [INFO] Booting worker with pid: 1975
[2021-09-06 07:43:05 +0000] [1965] [INFO] Handling signal: term
[2021-09-06 07:43:05 +0000] [1975] [INFO] Worker exiting (pid: 1975)
[2021-09-06 07:43:05 +0000] [1965] [INFO] Shutting down: Master
[2021-09-06 07:43:06 +0000] [2013] [INFO] Starting gunicorn 20.1.0
[2021-09-06 07:43:06 +0000] [2013] [INFO] Listening at: http://0.0.0.0:8080 (2013)
[2021-09-06 07:43:06 +0000] [2013] [INFO] Using worker: sync
[2021-09-06 07:43:06 +0000] [2023] [INFO] Booting worker with pid: 2023
[2021-09-06 07:44:54 +0000] [2013] [INFO] Handling signal: winch
[2021-09-06 07:50:34 +0000] [2013] [INFO] Handling signal: term
[2021-09-06 07:50:34 +0000] [2023] [INFO] Worker exiting (pid: 2023)
[2021-09-06 07:50:34 +0000] [2013] [INFO] Shutting down: Master
[2021-09-06 07:50:35 +0000] [2157] [INFO] Starting gunicorn 20.1.0
[2021-09-06 07:50:35 +0000] [2157] [INFO] Listening at: http://0.0.0.0:8080 (2157)
[2021-09-06 07:50:35 +0000] [2157] [INFO] Using worker: sync
[2021-09-06 07:50:35 +0000] [2164] [INFO] Booting worker with pid: 2164
[2021-09-06 07:50:36 +0000] [2164] [ERROR] Error handling request /
Traceback (most recent call last):
  File "/opt/virtualenvs/python3/lib/python3.8/site-packages/django/core/handlers/exception.py", line 34, in inner
    response = get_response(request)
  File "/opt/virtualenvs/python3/lib/python3.8/site-packages/django/core/handlers/base.py", line 100, in _get_response
    resolver_match = resolver.resolve(request.path_info)
  File "/opt/virtualenvs/python3/lib/python3.8/site-packages/django/urls/resolvers.py", line 544, in resolve
    for pattern in self.url_patterns:
  File "/opt/virtualenvs/python3/lib/python3.8/site-packages/django/utils/functional.py", line 48, in __get__
    res = instance.__dict__[self.name] = self.func(instance)
  File "/opt/virtualenvs/python3/lib/python3.8/site-packages/django/urls/resolvers.py", line 588, in url_patterns
    patterns = getattr(self.urlconf_module, "urlpatterns", self.urlconf_module)
  File "/opt/virtualenvs/python3/lib/python3.8/site-packages/django/utils/functional.py", line 48, in __get__
    res = instance.__dict__[self.name] = self.func(instance)
  File "/opt/virtualenvs/python3/lib/python3.8/site-packages/django/urls/resolvers.py", line 581, in urlconf_module
    return import_module(self.urlconf_name)
  File "/usr/lib/python3.8/importlib/__init__.py", line 127, in import_module
    return _bootstrap._gcd_import(name[level:], package, level)
  File "<frozen importlib._bootstrap>", line 1014, in _gcd_import
  File "<frozen importlib._bootstrap>", line 991, in _find_and_load
  File "<frozen importlib._bootstrap>", line 975, in _find_and_load_unlocked
  File "<frozen importlib._bootstrap>", line 671, in _load_unlocked
  File "<frozen importlib._bootstrap_external>", line 848, in exec_module
  File "<frozen importlib._bootstrap>", line 219, in _call_with_frames_removed
  File "/home/runner/wws/mysite/urls.py", line 18, in <module>
    import home.views
  File "/home/runner/wws/home/views.py", line 3, in <module>
    from django.backends.base.SessionBase import clear_expired
ModuleNotFoundError: No module named 'django.backends'

During handling of the above exception, another exception occurred:

Traceback (most recent call last):
  File "/opt/virtualenvs/python3/lib/python3.8/site-packages/django/core/handlers/exception.py", line 34, in inner
    response = get_response(request)
  File "/opt/virtualenvs/python3/lib/python3.8/site-packages/django/utils/deprecation.py", line 94, in __call__
    response = response or self.get_response(request)
  File "/opt/virtualenvs/python3/lib/python3.8/site-packages/django/core/handlers/exception.py", line 36, in inner
    response = response_for_exception(request, exc)
  File "/opt/virtualenvs/python3/lib/python3.8/site-packages/django/core/handlers/exception.py", line 90, in response_for_exception
    response = handle_uncaught_exception(request, get_resolver(get_urlconf()), sys.exc_info())
  File "/opt/virtualenvs/python3/lib/python3.8/site-packages/django/core/handlers/exception.py", line 128, in handle_uncaught_exception
    callback, param_dict = resolver.resolve_error_handler(500)
  File "/opt/virtualenvs/python3/lib/python3.8/site-packages/django/urls/resolvers.py", line 601, in resolve_error_handler
    callback = getattr(self.urlconf_module, 'handler%s' % view_type, None)
  File "/opt/virtualenvs/python3/lib/python3.8/site-packages/django/utils/functional.py", line 48, in __get__
    res = instance.__dict__[self.name] = self.func(instance)
  File "/opt/virtualenvs/python3/lib/python3.8/site-packages/django/urls/resolvers.py", line 581, in urlconf_module
    return import_module(self.urlconf_name)
  File "/usr/lib/python3.8/importlib/__init__.py", line 127, in import_module
    return _bootstrap._gcd_import(name[level:], package, level)
  File "<frozen importlib._bootstrap>", line 1014, in _gcd_import
  File "<frozen importlib._bootstrap>", line 991, in _find_and_load
  File "<frozen importlib._bootstrap>", line 975, in _find_and_load_unlocked
  File "<frozen importlib._bootstrap>", line 671, in _load_unlocked
  File "<frozen importlib._bootstrap_external>", line 848, in exec_module
  File "<frozen importlib._bootstrap>", line 219, in _call_with_frames_removed
  File "/home/runner/wws/mysite/urls.py", line 18, in <module>
    import home.views
  File "/home/runner/wws/home/views.py", line 3, in <module>
    from django.backends.base.SessionBase import clear_expired
ModuleNotFoundError: No module named 'django.backends'

During handling of the above exception, another exception occurred:

Traceback (most recent call last):
  File "/opt/virtualenvs/python3/lib/python3.8/site-packages/django/core/handlers/exception.py", line 34, in inner
    response = get_response(request)
  File "/opt/virtualenvs/python3/lib/python3.8/site-packages/django/utils/deprecation.py", line 94, in __call__
    response = response or self.get_response(request)
  File "/opt/virtualenvs/python3/lib/python3.8/site-packages/django/core/handlers/exception.py", line 36, in inner
    response = response_for_exception(request, exc)
  File "/opt/virtualenvs/python3/lib/python3.8/site-packages/django/core/handlers/exception.py", line 90, in response_for_exception
    response = handle_uncaught_exception(request, get_resolver(get_urlconf()), sys.exc_info())
  File "/opt/virtualenvs/python3/lib/python3.8/site-packages/django/core/handlers/exception.py", line 128, in handle_uncaught_exception
    callback, param_dict = resolver.resolve_error_handler(500)
  File "/opt/virtualenvs/python3/lib/python3.8/site-packages/django/urls/resolvers.py", line 601, in resolve_error_handler
    callback = getattr(self.urlconf_module, 'handler%s' % view_type, None)
  File "/opt/virtualenvs/python3/lib/python3.8/site-packages/django/utils/functional.py", line 48, in __get__
    res = instance.__dict__[self.name] = self.func(instance)
  File "/opt/virtualenvs/python3/lib/python3.8/site-packages/django/urls/resolvers.py", line 581, in urlconf_module
    return import_module(self.urlconf_name)
  File "/usr/lib/python3.8/importlib/__init__.py", line 127, in import_module
    return _bootstrap._gcd_import(name[level:], package, level)
  File "<frozen importlib._bootstrap>", line 1014, in _gcd_import
  File "<frozen importlib._bootstrap>", line 991, in _find_and_load
  File "<frozen importlib._bootstrap>", line 975, in _find_and_load_unlocked
  File "<frozen importlib._bootstrap>", line 671, in _load_unlocked
  File "<frozen importlib._bootstrap_external>", line 848, in exec_module
  File "<frozen importlib._bootstrap>", line 219, in _call_with_frames_removed
  File "/home/runner/wws/mysite/urls.py", line 18, in <module>
    import home.views
  File "/home/runner/wws/home/views.py", line 3, in <module>
    from django.backends.base.SessionBase import clear_expired
ModuleNotFoundError: No module named 'django.backends'

During handling of the above exception, another exception occurred:

Traceback (most recent call last):
  File "/opt/virtualenvs/python3/lib/python3.8/site-packages/django/core/handlers/exception.py", line 34, in inner
    response = get_response(request)
  File "/opt/virtualenvs/python3/lib/python3.8/site-packages/django/utils/deprecation.py", line 94, in __call__
    response = response or self.get_response(request)
  File "/opt/virtualenvs/python3/lib/python3.8/site-packages/django/core/handlers/exception.py", line 36, in inner
    response = response_for_exception(request, exc)
  File "/opt/virtualenvs/python3/lib/python3.8/site-packages/django/core/handlers/exception.py", line 90, in response_for_exception
    response = handle_uncaught_exception(request, get_resolver(get_urlconf()), sys.exc_info())
  File "/opt/virtualenvs/python3/lib/python3.8/site-packages/django/core/handlers/exception.py", line 128, in handle_uncaught_exception
    callback, param_dict = resolver.resolve_error_handler(500)
  File "/opt/virtualenvs/python3/lib/python3.8/site-packages/django/urls/resolvers.py", line 601, in resolve_error_handler
    callback = getattr(self.urlconf_module, 'handler%s' % view_type, None)
  File "/opt/virtualenvs/python3/lib/python3.8/site-packages/django/utils/functional.py", line 48, in __get__
    res = instance.__dict__[self.name] = self.func(instance)
  File "/opt/virtualenvs/python3/lib/python3.8/site-packages/django/urls/resolvers.py", line 581, in urlconf_module
    return import_module(self.urlconf_name)
  File "/usr/lib/python3.8/importlib/__init__.py", line 127, in import_module
    return _bootstrap._gcd_import(name[level:], package, level)
  File "<frozen importlib._bootstrap>", line 1014, in _gcd_import
  File "<frozen importlib._bootstrap>", line 991, in _find_and_load
  File "<frozen importlib._bootstrap>", line 975, in _find_and_load_unlocked
  File "<frozen importlib._bootstrap>", line 671, in _load_unlocked
  File "<frozen importlib._bootstrap_external>", line 848, in exec_module
  File "<frozen importlib._bootstrap>", line 219, in _call_with_frames_removed
  File "/home/runner/wws/mysite/urls.py", line 18, in <module>
    import home.views
  File "/home/runner/wws/home/views.py", line 3, in <module>
    from django.backends.base.SessionBase import clear_expired
ModuleNotFoundError: No module named 'django.backends'

During handling of the above exception, another exception occurred:

Traceback (most recent call last):
  File "/opt/virtualenvs/python3/lib/python3.8/site-packages/django/core/handlers/exception.py", line 34, in inner
    response = get_response(request)
  File "/opt/virtualenvs/python3/lib/python3.8/site-packages/django/utils/deprecation.py", line 94, in __call__
    response = response or self.get_response(request)
  File "/opt/virtualenvs/python3/lib/python3.8/site-packages/django/core/handlers/exception.py", line 36, in inner
    response = response_for_exception(request, exc)
  File "/opt/virtualenvs/python3/lib/python3.8/site-packages/django/core/handlers/exception.py", line 90, in response_for_exception
    response = handle_uncaught_exception(request, get_resolver(get_urlconf()), sys.exc_info())
  File "/opt/virtualenvs/python3/lib/python3.8/site-packages/django/core/handlers/exception.py", line 128, in handle_uncaught_exception
    callback, param_dict = resolver.resolve_error_handler(500)
  File "/opt/virtualenvs/python3/lib/python3.8/site-packages/django/urls/resolvers.py", line 601, in resolve_error_handler
    callback = getattr(self.urlconf_module, 'handler%s' % view_type, None)
  File "/opt/virtualenvs/python3/lib/python3.8/site-packages/django/utils/functional.py", line 48, in __get__
    res = instance.__dict__[self.name] = self.func(instance)
  File "/opt/virtualenvs/python3/lib/python3.8/site-packages/django/urls/resolvers.py", line 581, in urlconf_module
    return import_module(self.urlconf_name)
  File "/usr/lib/python3.8/importlib/__init__.py", line 127, in import_module
    return _bootstrap._gcd_import(name[level:], package, level)
  File "<frozen importlib._bootstrap>", line 1014, in _gcd_import
  File "<frozen importlib._bootstrap>", line 991, in _find_and_load
  File "<frozen importlib._bootstrap>", line 975, in _find_and_load_unlocked
  File "<frozen importlib._bootstrap>", line 671, in _load_unlocked
  File "<frozen importlib._bootstrap_external>", line 848, in exec_module
  File "<frozen importlib._bootstrap>", line 219, in _call_with_frames_removed
  File "/home/runner/wws/mysite/urls.py", line 18, in <module>
    import home.views
  File "/home/runner/wws/home/views.py", line 3, in <module>
    from django.backends.base.SessionBase import clear_expired
ModuleNotFoundError: No module named 'django.backends'

During handling of the above exception, another exception occurred:

Traceback (most recent call last):
  File "/opt/virtualenvs/python3/lib/python3.8/site-packages/django/core/handlers/exception.py", line 34, in inner
    response = get_response(request)
  File "/opt/virtualenvs/python3/lib/python3.8/site-packages/django/utils/deprecation.py", line 94, in __call__
    response = response or self.get_response(request)
  File "/opt/virtualenvs/python3/lib/python3.8/site-packages/django/core/handlers/exception.py", line 36, in inner
    response = response_for_exception(request, exc)
  File "/opt/virtualenvs/python3/lib/python3.8/site-packages/django/core/handlers/exception.py", line 90, in response_for_exception
    response = handle_uncaught_exception(request, get_resolver(get_urlconf()), sys.exc_info())
  File "/opt/virtualenvs/python3/lib/python3.8/site-packages/django/core/handlers/exception.py", line 128, in handle_uncaught_exception
    callback, param_dict = resolver.resolve_error_handler(500)
  File "/opt/virtualenvs/python3/lib/python3.8/site-packages/django/urls/resolvers.py", line 601, in resolve_error_handler
    callback = getattr(self.urlconf_module, 'handler%s' % view_type, None)
  File "/opt/virtualenvs/python3/lib/python3.8/site-packages/django/utils/functional.py", line 48, in __get__
    res = instance.__dict__[self.name] = self.func(instance)
  File "/opt/virtualenvs/python3/lib/python3.8/site-packages/django/urls/resolvers.py", line 581, in urlconf_module
    return import_module(self.urlconf_name)
  File "/usr/lib/python3.8/importlib/__init__.py", line 127, in import_module
    return _bootstrap._gcd_import(name[level:], package, level)
  File "<frozen importlib._bootstrap>", line 1014, in _gcd_import
  File "<frozen importlib._bootstrap>", line 991, in _find_and_load
  File "<frozen importlib._bootstrap>", line 975, in _find_and_load_unlocked
  File "<frozen importlib._bootstrap>", line 671, in _load_unlocked
  File "<frozen importlib._bootstrap_external>", line 848, in exec_module
  File "<frozen importlib._bootstrap>", line 219, in _call_with_frames_removed
  File "/home/runner/wws/mysite/urls.py", line 18, in <module>
    import home.views
  File "/home/runner/wws/home/views.py", line 3, in <module>
    from django.backends.base.SessionBase import clear_expired
ModuleNotFoundError: No module named 'django.backends'

During handling of the above exception, another exception occurred:

Traceback (most recent call last):
  File "/opt/virtualenvs/python3/lib/python3.8/site-packages/django/core/handlers/exception.py", line 34, in inner
    response = get_response(request)
  File "/opt/virtualenvs/python3/lib/python3.8/site-packages/django/utils/deprecation.py", line 94, in __call__
    response = response or self.get_response(request)
  File "/opt/virtualenvs/python3/lib/python3.8/site-packages/django/core/handlers/exception.py", line 36, in inner
    response = response_for_exception(request, exc)
  File "/opt/virtualenvs/python3/lib/python3.8/site-packages/django/core/handlers/exception.py", line 90, in response_for_exception
    response = handle_uncaught_exception(request, get_resolver(get_urlconf()), sys.exc_info())
  File "/opt/virtualenvs/python3/lib/python3.8/site-packages/django/core/handlers/exception.py", line 128, in handle_uncaught_exception
    callback, param_dict = resolver.resolve_error_handler(500)
  File "/opt/virtualenvs/python3/lib/python3.8/site-packages/django/urls/resolvers.py", line 601, in resolve_error_handler
    callback = getattr(self.urlconf_module, 'handler%s' % view_type, None)
  File "/opt/virtualenvs/python3/lib/python3.8/site-packages/django/utils/functional.py", line 48, in __get__
    res = instance.__dict__[self.name] = self.func(instance)
  File "/opt/virtualenvs/python3/lib/python3.8/site-packages/django/urls/resolvers.py", line 581, in urlconf_module
    return import_module(self.urlconf_name)
  File "/usr/lib/python3.8/importlib/__init__.py", line 127, in import_module
    return _bootstrap._gcd_import(name[level:], package, level)
  File "<frozen importlib._bootstrap>", line 1014, in _gcd_import
  File "<frozen importlib._bootstrap>", line 991, in _find_and_load
  File "<frozen importlib._bootstrap>", line 975, in _find_and_load_unlocked
  File "<frozen importlib._bootstrap>", line 671, in _load_unlocked
  File "<frozen importlib._bootstrap_external>", line 848, in exec_module
  File "<frozen importlib._bootstrap>", line 219, in _call_with_frames_removed
  File "/home/runner/wws/mysite/urls.py", line 18, in <module>
    import home.views
  File "/home/runner/wws/home/views.py", line 3, in <module>
    from django.backends.base.SessionBase import clear_expired
ModuleNotFoundError: No module named 'django.backends'

During handling of the above exception, another exception occurred:

Traceback (most recent call last):
  File "/opt/virtualenvs/python3/lib/python3.8/site-packages/django/core/handlers/exception.py", line 34, in inner
    response = get_response(request)
  File "/opt/virtualenvs/python3/lib/python3.8/site-packages/django/utils/deprecation.py", line 94, in __call__
    response = response or self.get_response(request)
  File "/opt/virtualenvs/python3/lib/python3.8/site-packages/django/core/handlers/exception.py", line 36, in inner
    response = response_for_exception(request, exc)
  File "/opt/virtualenvs/python3/lib/python3.8/site-packages/django/core/handlers/exception.py", line 90, in response_for_exception
    response = handle_uncaught_exception(request, get_resolver(get_urlconf()), sys.exc_info())
  File "/opt/virtualenvs/python3/lib/python3.8/site-packages/django/core/handlers/exception.py", line 128, in handle_uncaught_exception
    callback, param_dict = resolver.resolve_error_handler(500)
  File "/opt/virtualenvs/python3/lib/python3.8/site-packages/django/urls/resolvers.py", line 601, in resolve_error_handler
    callback = getattr(self.urlconf_module, 'handler%s' % view_type, None)
  File "/opt/virtualenvs/python3/lib/python3.8/site-packages/django/utils/functional.py", line 48, in __get__
    res = instance.__dict__[self.name] = self.func(instance)
  File "/opt/virtualenvs/python3/lib/python3.8/site-packages/django/urls/resolvers.py", line 581, in urlconf_module
    return import_module(self.urlconf_name)
  File "/usr/lib/python3.8/importlib/__init__.py", line 127, in import_module
    return _bootstrap._gcd_import(name[level:], package, level)
  File "<frozen importlib._bootstrap>", line 1014, in _gcd_import
  File "<frozen importlib._bootstrap>", line 991, in _find_and_load
  File "<frozen importlib._bootstrap>", line 975, in _find_and_load_unlocked
  File "<frozen importlib._bootstrap>", line 671, in _load_unlocked
  File "<frozen importlib._bootstrap_external>", line 848, in exec_module
  File "<frozen importlib._bootstrap>", line 219, in _call_with_frames_removed
  File "/home/runner/wws/mysite/urls.py", line 18, in <module>
    import home.views
  File "/home/runner/wws/home/views.py", line 3, in <module>
    from django.backends.base.SessionBase import clear_expired
ModuleNotFoundError: No module named 'django.backends'

During handling of the above exception, another exception occurred:

Traceback (most recent call last):
  File "/opt/virtualenvs/python3/lib/python3.8/site-packages/gunicorn/workers/sync.py", line 136, in handle
    self.handle_request(listener, req, client, addr)
  File "/opt/virtualenvs/python3/lib/python3.8/site-packages/gunicorn/workers/sync.py", line 179, in handle_request
    respiter = self.wsgi(environ, resp.start_response)
  File "/opt/virtualenvs/python3/lib/python3.8/site-packages/whitenoise/base.py", line 85, in __call__
    return self.application(environ, start_response)
  File "/opt/virtualenvs/python3/lib/python3.8/site-packages/django/core/handlers/wsgi.py", line 133, in __call__
    response = self.get_response(request)
  File "/opt/virtualenvs/python3/lib/python3.8/site-packages/django/core/handlers/base.py", line 75, in get_response
    response = self._middleware_chain(request)
  File "/opt/virtualenvs/python3/lib/python3.8/site-packages/django/core/handlers/exception.py", line 36, in inner
    response = response_for_exception(request, exc)
  File "/opt/virtualenvs/python3/lib/python3.8/site-packages/django/core/handlers/exception.py", line 90, in response_for_exception
    response = handle_uncaught_exception(request, get_resolver(get_urlconf()), sys.exc_info())
  File "/opt/virtualenvs/python3/lib/python3.8/site-packages/django/core/handlers/exception.py", line 128, in handle_uncaught_exception
    callback, param_dict = resolver.resolve_error_handler(500)
  File "/opt/virtualenvs/python3/lib/python3.8/site-packages/django/urls/resolvers.py", line 601, in resolve_error_handler
    callback = getattr(self.urlconf_module, 'handler%s' % view_type, None)
  File "/opt/virtualenvs/python3/lib/python3.8/site-packages/django/utils/functional.py", line 48, in __get__
    res = instance.__dict__[self.name] = self.func(instance)
  File "/opt/virtualenvs/python3/lib/python3.8/site-packages/django/urls/resolvers.py", line 581, in urlconf_module
    return import_module(self.urlconf_name)
  File "/usr/lib/python3.8/importlib/__init__.py", line 127, in import_module
    return _bootstrap._gcd_import(name[level:], package, level)
  File "<frozen importlib._bootstrap>", line 1014, in _gcd_import
  File "<frozen importlib._bootstrap>", line 991, in _find_and_load
  File "<frozen importlib._bootstrap>", line 975, in _find_and_load_unlocked
  File "<frozen importlib._bootstrap>", line 671, in _load_unlocked
  File "<frozen importlib._bootstrap_external>", line 848, in exec_module
  File "<frozen importlib._bootstrap>", line 219, in _call_with_frames_removed
  File "/home/runner/wws/mysite/urls.py", line 18, in <module>
    import home.views
  File "/home/runner/wws/home/views.py", line 3, in <module>
    from django.backends.base.SessionBase import clear_expired
ModuleNotFoundError: No module named 'django.backends'
[2021-09-06 07:50:54 +0000] [2164] [ERROR] Error handling request /
Traceback (most recent call last):
  File "/opt/virtualenvs/python3/lib/python3.8/site-packages/django/core/handlers/exception.py", line 34, in inner
    response = get_response(request)
  File "/opt/virtualenvs/python3/lib/python3.8/site-packages/django/core/handlers/base.py", line 100, in _get_response
    resolver_match = resolver.resolve(request.path_info)
  File "/opt/virtualenvs/python3/lib/python3.8/site-packages/django/urls/resolvers.py", line 544, in resolve
    for pattern in self.url_patterns:
  File "/opt/virtualenvs/python3/lib/python3.8/site-packages/django/utils/functional.py", line 48, in __get__
    res = instance.__dict__[self.name] = self.func(instance)
  File "/opt/virtualenvs/python3/lib/python3.8/site-packages/django/urls/resolvers.py", line 588, in url_patterns
    patterns = getattr(self.urlconf_module, "urlpatterns", self.urlconf_module)
  File "/opt/virtualenvs/python3/lib/python3.8/site-packages/django/utils/functional.py", line 48, in __get__
    res = instance.__dict__[self.name] = self.func(instance)
  File "/opt/virtualenvs/python3/lib/python3.8/site-packages/django/urls/resolvers.py", line 581, in urlconf_module
    return import_module(self.urlconf_name)
  File "/usr/lib/python3.8/importlib/__init__.py", line 127, in import_module
    return _bootstrap._gcd_import(name[level:], package, level)
  File "<frozen importlib._bootstrap>", line 1014, in _gcd_import
  File "<frozen importlib._bootstrap>", line 991, in _find_and_load
  File "<frozen importlib._bootstrap>", line 975, in _find_and_load_unlocked
  File "<frozen importlib._bootstrap>", line 671, in _load_unlocked
  File "<frozen importlib._bootstrap_external>", line 848, in exec_module
  File "<frozen importlib._bootstrap>", line 219, in _call_with_frames_removed
  File "/home/runner/wws/mysite/urls.py", line 18, in <module>
    import home.views
  File "/home/runner/wws/home/views.py", line 3, in <module>
    from django.backends.base.SessionBase import clear_expired
ModuleNotFoundError: No module named 'django.backends'

During handling of the above exception, another exception occurred:

Traceback (most recent call last):
  File "/opt/virtualenvs/python3/lib/python3.8/site-packages/django/core/handlers/exception.py", line 34, in inner
    response = get_response(request)
  File "/opt/virtualenvs/python3/lib/python3.8/site-packages/django/utils/deprecation.py", line 94, in __call__
    response = response or self.get_response(request)
  File "/opt/virtualenvs/python3/lib/python3.8/site-packages/django/core/handlers/exception.py", line 36, in inner
    response = response_for_exception(request, exc)
  File "/opt/virtualenvs/python3/lib/python3.8/site-packages/django/core/handlers/exception.py", line 90, in response_for_exception
    response = handle_uncaught_exception(request, get_resolver(get_urlconf()), sys.exc_info())
  File "/opt/virtualenvs/python3/lib/python3.8/site-packages/django/core/handlers/exception.py", line 128, in handle_uncaught_exception
    callback, param_dict = resolver.resolve_error_handler(500)
  File "/opt/virtualenvs/python3/lib/python3.8/site-packages/django/urls/resolvers.py", line 601, in resolve_error_handler
    callback = getattr(self.urlconf_module, 'handler%s' % view_type, None)
  File "/opt/virtualenvs/python3/lib/python3.8/site-packages/django/utils/functional.py", line 48, in __get__
    res = instance.__dict__[self.name] = self.func(instance)
  File "/opt/virtualenvs/python3/lib/python3.8/site-packages/django/urls/resolvers.py", line 581, in urlconf_module
    return import_module(self.urlconf_name)
  File "/usr/lib/python3.8/importlib/__init__.py", line 127, in import_module
    return _bootstrap._gcd_import(name[level:], package, level)
  File "<frozen importlib._bootstrap>", line 1014, in _gcd_import
  File "<frozen importlib._bootstrap>", line 991, in _find_and_load
  File "<frozen importlib._bootstrap>", line 975, in _find_and_load_unlocked
  File "<frozen importlib._bootstrap>", line 671, in _load_unlocked
  File "<frozen importlib._bootstrap_external>", line 848, in exec_module
  File "<frozen importlib._bootstrap>", line 219, in _call_with_frames_removed
  File "/home/runner/wws/mysite/urls.py", line 18, in <module>
    import home.views
  File "/home/runner/wws/home/views.py", line 3, in <module>
    from django.backends.base.SessionBase import clear_expired
ModuleNotFoundError: No module named 'django.backends'

During handling of the above exception, another exception occurred:

Traceback (most recent call last):
  File "/opt/virtualenvs/python3/lib/python3.8/site-packages/django/core/handlers/exception.py", line 34, in inner
    response = get_response(request)
  File "/opt/virtualenvs/python3/lib/python3.8/site-packages/django/utils/deprecation.py", line 94, in __call__
    response = response or self.get_response(request)
  File "/opt/virtualenvs/python3/lib/python3.8/site-packages/django/core/handlers/exception.py", line 36, in inner
    response = response_for_exception(request, exc)
  File "/opt/virtualenvs/python3/lib/python3.8/site-packages/django/core/handlers/exception.py", line 90, in response_for_exception
    response = handle_uncaught_exception(request, get_resolver(get_urlconf()), sys.exc_info())
  File "/opt/virtualenvs/python3/lib/python3.8/site-packages/django/core/handlers/exception.py", line 128, in handle_uncaught_exception
    callback, param_dict = resolver.resolve_error_handler(500)
  File "/opt/virtualenvs/python3/lib/python3.8/site-packages/django/urls/resolvers.py", line 601, in resolve_error_handler
    callback = getattr(self.urlconf_module, 'handler%s' % view_type, None)
  File "/opt/virtualenvs/python3/lib/python3.8/site-packages/django/utils/functional.py", line 48, in __get__
    res = instance.__dict__[self.name] = self.func(instance)
  File "/opt/virtualenvs/python3/lib/python3.8/site-packages/django/urls/resolvers.py", line 581, in urlconf_module
    return import_module(self.urlconf_name)
  File "/usr/lib/python3.8/importlib/__init__.py", line 127, in import_module
    return _bootstrap._gcd_import(name[level:], package, level)
  File "<frozen importlib._bootstrap>", line 1014, in _gcd_import
  File "<frozen importlib._bootstrap>", line 991, in _find_and_load
  File "<frozen importlib._bootstrap>", line 975, in _find_and_load_unlocked
  File "<frozen importlib._bootstrap>", line 671, in _load_unlocked
  File "<frozen importlib._bootstrap_external>", line 848, in exec_module
  File "<frozen importlib._bootstrap>", line 219, in _call_with_frames_removed
  File "/home/runner/wws/mysite/urls.py", line 18, in <module>
    import home.views
  File "/home/runner/wws/home/views.py", line 3, in <module>
    from django.backends.base.SessionBase import clear_expired
ModuleNotFoundError: No module named 'django.backends'

During handling of the above exception, another exception occurred:

Traceback (most recent call last):
  File "/opt/virtualenvs/python3/lib/python3.8/site-packages/django/core/handlers/exception.py", line 34, in inner
    response = get_response(request)
  File "/opt/virtualenvs/python3/lib/python3.8/site-packages/django/utils/deprecation.py", line 94, in __call__
    response = response or self.get_response(request)
  File "/opt/virtualenvs/python3/lib/python3.8/site-packages/django/core/handlers/exception.py", line 36, in inner
    response = response_for_exception(request, exc)
  File "/opt/virtualenvs/python3/lib/python3.8/site-packages/django/core/handlers/exception.py", line 90, in response_for_exception
    response = handle_uncaught_exception(request, get_resolver(get_urlconf()), sys.exc_info())
  File "/opt/virtualenvs/python3/lib/python3.8/site-packages/django/core/handlers/exception.py", line 128, in handle_uncaught_exception
    callback, param_dict = resolver.resolve_error_handler(500)
  File "/opt/virtualenvs/python3/lib/python3.8/site-packages/django/urls/resolvers.py", line 601, in resolve_error_handler
    callback = getattr(self.urlconf_module, 'handler%s' % view_type, None)
  File "/opt/virtualenvs/python3/lib/python3.8/site-packages/django/utils/functional.py", line 48, in __get__
    res = instance.__dict__[self.name] = self.func(instance)
  File "/opt/virtualenvs/python3/lib/python3.8/site-packages/django/urls/resolvers.py", line 581, in urlconf_module
    return import_module(self.urlconf_name)
  File "/usr/lib/python3.8/importlib/__init__.py", line 127, in import_module
    return _bootstrap._gcd_import(name[level:], package, level)
  File "<frozen importlib._bootstrap>", line 1014, in _gcd_import
  File "<frozen importlib._bootstrap>", line 991, in _find_and_load
  File "<frozen importlib._bootstrap>", line 975, in _find_and_load_unlocked
  File "<frozen importlib._bootstrap>", line 671, in _load_unlocked
  File "<frozen importlib._bootstrap_external>", line 848, in exec_module
  File "<frozen importlib._bootstrap>", line 219, in _call_with_frames_removed
  File "/home/runner/wws/mysite/urls.py", line 18, in <module>
    import home.views
  File "/home/runner/wws/home/views.py", line 3, in <module>
    from django.backends.base.SessionBase import clear_expired
ModuleNotFoundError: No module named 'django.backends'

During handling of the above exception, another exception occurred:

Traceback (most recent call last):
  File "/opt/virtualenvs/python3/lib/python3.8/site-packages/django/core/handlers/exception.py", line 34, in inner
    response = get_response(request)
  File "/opt/virtualenvs/python3/lib/python3.8/site-packages/django/utils/deprecation.py", line 94, in __call__
    response = response or self.get_response(request)
  File "/opt/virtualenvs/python3/lib/python3.8/site-packages/django/core/handlers/exception.py", line 36, in inner
    response = response_for_exception(request, exc)
  File "/opt/virtualenvs/python3/lib/python3.8/site-packages/django/core/handlers/exception.py", line 90, in response_for_exception
    response = handle_uncaught_exception(request, get_resolver(get_urlconf()), sys.exc_info())
  File "/opt/virtualenvs/python3/lib/python3.8/site-packages/django/core/handlers/exception.py", line 128, in handle_uncaught_exception
    callback, param_dict = resolver.resolve_error_handler(500)
  File "/opt/virtualenvs/python3/lib/python3.8/site-packages/django/urls/resolvers.py", line 601, in resolve_error_handler
    callback = getattr(self.urlconf_module, 'handler%s' % view_type, None)
  File "/opt/virtualenvs/python3/lib/python3.8/site-packages/django/utils/functional.py", line 48, in __get__
    res = instance.__dict__[self.name] = self.func(instance)
  File "/opt/virtualenvs/python3/lib/python3.8/site-packages/django/urls/resolvers.py", line 581, in urlconf_module
    return import_module(self.urlconf_name)
  File "/usr/lib/python3.8/importlib/__init__.py", line 127, in import_module
    return _bootstrap._gcd_import(name[level:], package, level)
  File "<frozen importlib._bootstrap>", line 1014, in _gcd_import
  File "<frozen importlib._bootstrap>", line 991, in _find_and_load
  File "<frozen importlib._bootstrap>", line 975, in _find_and_load_unlocked
  File "<frozen importlib._bootstrap>", line 671, in _load_unlocked
  File "<frozen importlib._bootstrap_external>", line 848, in exec_module
  File "<frozen importlib._bootstrap>", line 219, in _call_with_frames_removed
  File "/home/runner/wws/mysite/urls.py", line 18, in <module>
    import home.views
  File "/home/runner/wws/home/views.py", line 3, in <module>
    from django.backends.base.SessionBase import clear_expired
ModuleNotFoundError: No module named 'django.backends'

During handling of the above exception, another exception occurred:

Traceback (most recent call last):
  File "/opt/virtualenvs/python3/lib/python3.8/site-packages/django/core/handlers/exception.py", line 34, in inner
    response = get_response(request)
  File "/opt/virtualenvs/python3/lib/python3.8/site-packages/django/utils/deprecation.py", line 94, in __call__
    response = response or self.get_response(request)
  File "/opt/virtualenvs/python3/lib/python3.8/site-packages/django/core/handlers/exception.py", line 36, in inner
    response = response_for_exception(request, exc)
  File "/opt/virtualenvs/python3/lib/python3.8/site-packages/django/core/handlers/exception.py", line 90, in response_for_exception
    response = handle_uncaught_exception(request, get_resolver(get_urlconf()), sys.exc_info())
  File "/opt/virtualenvs/python3/lib/python3.8/site-packages/django/core/handlers/exception.py", line 128, in handle_uncaught_exception
    callback, param_dict = resolver.resolve_error_handler(500)
  File "/opt/virtualenvs/python3/lib/python3.8/site-packages/django/urls/resolvers.py", line 601, in resolve_error_handler
    callback = getattr(self.urlconf_module, 'handler%s' % view_type, None)
  File "/opt/virtualenvs/python3/lib/python3.8/site-packages/django/utils/functional.py", line 48, in __get__
    res = instance.__dict__[self.name] = self.func(instance)
  File "/opt/virtualenvs/python3/lib/python3.8/site-packages/django/urls/resolvers.py", line 581, in urlconf_module
    return import_module(self.urlconf_name)
  File "/usr/lib/python3.8/importlib/__init__.py", line 127, in import_module
    return _bootstrap._gcd_import(name[level:], package, level)
  File "<frozen importlib._bootstrap>", line 1014, in _gcd_import
  File "<frozen importlib._bootstrap>", line 991, in _find_and_load
  File "<frozen importlib._bootstrap>", line 975, in _find_and_load_unlocked
  File "<frozen importlib._bootstrap>", line 671, in _load_unlocked
  File "<frozen importlib._bootstrap_external>", line 848, in exec_module
  File "<frozen importlib._bootstrap>", line 219, in _call_with_frames_removed
  File "/home/runner/wws/mysite/urls.py", line 18, in <module>
    import home.views
  File "/home/runner/wws/home/views.py", line 3, in <module>
    from django.backends.base.SessionBase import clear_expired
ModuleNotFoundError: No module named 'django.backends'

During handling of the above exception, another exception occurred:

Traceback (most recent call last):
  File "/opt/virtualenvs/python3/lib/python3.8/site-packages/django/core/handlers/exception.py", line 34, in inner
    response = get_response(request)
  File "/opt/virtualenvs/python3/lib/python3.8/site-packages/django/utils/deprecation.py", line 94, in __call__
    response = response or self.get_response(request)
  File "/opt/virtualenvs/python3/lib/python3.8/site-packages/django/core/handlers/exception.py", line 36, in inner
    response = response_for_exception(request, exc)
  File "/opt/virtualenvs/python3/lib/python3.8/site-packages/django/core/handlers/exception.py", line 90, in response_for_exception
    response = handle_uncaught_exception(request, get_resolver(get_urlconf()), sys.exc_info())
  File "/opt/virtualenvs/python3/lib/python3.8/site-packages/django/core/handlers/exception.py", line 128, in handle_uncaught_exception
    callback, param_dict = resolver.resolve_error_handler(500)
  File "/opt/virtualenvs/python3/lib/python3.8/site-packages/django/urls/resolvers.py", line 601, in resolve_error_handler
    callback = getattr(self.urlconf_module, 'handler%s' % view_type, None)
  File "/opt/virtualenvs/python3/lib/python3.8/site-packages/django/utils/functional.py", line 48, in __get__
    res = instance.__dict__[self.name] = self.func(instance)
  File "/opt/virtualenvs/python3/lib/python3.8/site-packages/django/urls/resolvers.py", line 581, in urlconf_module
    return import_module(self.urlconf_name)
  File "/usr/lib/python3.8/importlib/__init__.py", line 127, in import_module
    return _bootstrap._gcd_import(name[level:], package, level)
  File "<frozen importlib._bootstrap>", line 1014, in _gcd_import
  File "<frozen importlib._bootstrap>", line 991, in _find_and_load
  File "<frozen importlib._bootstrap>", line 975, in _find_and_load_unlocked
  File "<frozen importlib._bootstrap>", line 671, in _load_unlocked
  File "<frozen importlib._bootstrap_external>", line 848, in exec_module
  File "<frozen importlib._bootstrap>", line 219, in _call_with_frames_removed
  File "/home/runner/wws/mysite/urls.py", line 18, in <module>
    import home.views
  File "/home/runner/wws/home/views.py", line 3, in <module>
    from django.backends.base.SessionBase import clear_expired
ModuleNotFoundError: No module named 'django.backends'

During handling of the above exception, another exception occurred:

Traceback (most recent call last):
  File "/opt/virtualenvs/python3/lib/python3.8/site-packages/django/core/handlers/exception.py", line 34, in inner
    response = get_response(request)
  File "/opt/virtualenvs/python3/lib/python3.8/site-packages/django/utils/deprecation.py", line 94, in __call__
    response = response or self.get_response(request)
  File "/opt/virtualenvs/python3/lib/python3.8/site-packages/django/core/handlers/exception.py", line 36, in inner
    response = response_for_exception(request, exc)
  File "/opt/virtualenvs/python3/lib/python3.8/site-packages/django/core/handlers/exception.py", line 90, in response_for_exception
    response = handle_uncaught_exception(request, get_resolver(get_urlconf()), sys.exc_info())
  File "/opt/virtualenvs/python3/lib/python3.8/site-packages/django/core/handlers/exception.py", line 128, in handle_uncaught_exception
    callback, param_dict = resolver.resolve_error_handler(500)
  File "/opt/virtualenvs/python3/lib/python3.8/site-packages/django/urls/resolvers.py", line 601, in resolve_error_handler
    callback = getattr(self.urlconf_module, 'handler%s' % view_type, None)
  File "/opt/virtualenvs/python3/lib/python3.8/site-packages/django/utils/functional.py", line 48, in __get__
    res = instance.__dict__[self.name] = self.func(instance)
  File "/opt/virtualenvs/python3/lib/python3.8/site-packages/django/urls/resolvers.py", line 581, in urlconf_module
    return import_module(self.urlconf_name)
  File "/usr/lib/python3.8/importlib/__init__.py", line 127, in import_module
    return _bootstrap._gcd_import(name[level:], package, level)
  File "<frozen importlib._bootstrap>", line 1014, in _gcd_import
  File "<frozen importlib._bootstrap>", line 991, in _find_and_load
  File "<frozen importlib._bootstrap>", line 975, in _find_and_load_unlocked
  File "<frozen importlib._bootstrap>", line 671, in _load_unlocked
  File "<frozen importlib._bootstrap_external>", line 848, in exec_module
  File "<frozen importlib._bootstrap>", line 219, in _call_with_frames_removed
  File "/home/runner/wws/mysite/urls.py", line 18, in <module>
    import home.views
  File "/home/runner/wws/home/views.py", line 3, in <module>
    from django.backends.base.SessionBase import clear_expired
ModuleNotFoundError: No module named 'django.backends'

During handling of the above exception, another exception occurred:

Traceback (most recent call last):
  File "/opt/virtualenvs/python3/lib/python3.8/site-packages/gunicorn/workers/sync.py", line 136, in handle
    self.handle_request(listener, req, client, addr)
  File "/opt/virtualenvs/python3/lib/python3.8/site-packages/gunicorn/workers/sync.py", line 179, in handle_request
    respiter = self.wsgi(environ, resp.start_response)
  File "/opt/virtualenvs/python3/lib/python3.8/site-packages/whitenoise/base.py", line 85, in __call__
    return self.application(environ, start_response)
  File "/opt/virtualenvs/python3/lib/python3.8/site-packages/django/core/handlers/wsgi.py", line 133, in __call__
    response = self.get_response(request)
  File "/opt/virtualenvs/python3/lib/python3.8/site-packages/django/core/handlers/base.py", line 75, in get_response
    response = self._middleware_chain(request)
  File "/opt/virtualenvs/python3/lib/python3.8/site-packages/django/core/handlers/exception.py", line 36, in inner
    response = response_for_exception(request, exc)
  File "/opt/virtualenvs/python3/lib/python3.8/site-packages/django/core/handlers/exception.py", line 90, in response_for_exception
    response = handle_uncaught_exception(request, get_resolver(get_urlconf()), sys.exc_info())
  File "/opt/virtualenvs/python3/lib/python3.8/site-packages/django/core/handlers/exception.py", line 128, in handle_uncaught_exception
    callback, param_dict = resolver.resolve_error_handler(500)
  File "/opt/virtualenvs/python3/lib/python3.8/site-packages/django/urls/resolvers.py", line 601, in resolve_error_handler
    callback = getattr(self.urlconf_module, 'handler%s' % view_type, None)
  File "/opt/virtualenvs/python3/lib/python3.8/site-packages/django/utils/functional.py", line 48, in __get__
    res = instance.__dict__[self.name] = self.func(instance)
  File "/opt/virtualenvs/python3/lib/python3.8/site-packages/django/urls/resolvers.py", line 581, in urlconf_module
    return import_module(self.urlconf_name)
  File "/usr/lib/python3.8/importlib/__init__.py", line 127, in import_module
    return _bootstrap._gcd_import(name[level:], package, level)
  File "<frozen importlib._bootstrap>", line 1014, in _gcd_import
  File "<frozen importlib._bootstrap>", line 991, in _find_and_load
  File "<frozen importlib._bootstrap>", line 975, in _find_and_load_unlocked
  File "<frozen importlib._bootstrap>", line 671, in _load_unlocked
  File "<frozen importlib._bootstrap_external>", line 848, in exec_module
  File "<frozen importlib._bootstrap>", line 219, in _call_with_frames_removed
  File "/home/runner/wws/mysite/urls.py", line 18, in <module>
    import home.views
  File "/home/runner/wws/home/views.py", line 3, in <module>
    from django.backends.base.SessionBase import clear_expired
ModuleNotFoundError: No module named 'django.backends'
[2021-09-06 07:50:55 +0000] [2164] [ERROR] Error handling request /favicon.ico
Traceback (most recent call last):
  File "/opt/virtualenvs/python3/lib/python3.8/site-packages/django/core/handlers/exception.py", line 34, in inner
    response = get_response(request)
  File "/opt/virtualenvs/python3/lib/python3.8/site-packages/django/utils/deprecation.py", line 93, in __call__
    response = self.process_request(request)
  File "/opt/virtualenvs/python3/lib/python3.8/site-packages/django/middleware/common.py", line 53, in process_request
    if self.should_redirect_with_slash(request):
  File "/opt/virtualenvs/python3/lib/python3.8/site-packages/django/middleware/common.py", line 71, in should_redirect_with_slash
    not is_valid_path(request.path_info, urlconf) and
  File "/opt/virtualenvs/python3/lib/python3.8/site-packages/django/urls/base.py", line 154, in is_valid_path
    resolve(path, urlconf)
  File "/opt/virtualenvs/python3/lib/python3.8/site-packages/django/urls/base.py", line 25, in resolve
    return get_resolver(urlconf).resolve(path)
  File "/opt/virtualenvs/python3/lib/python3.8/site-packages/django/urls/resolvers.py", line 544, in resolve
    for pattern in self.url_patterns:
  File "/opt/virtualenvs/python3/lib/python3.8/site-packages/django/utils/functional.py", line 48, in __get__
    res = instance.__dict__[self.name] = self.func(instance)
  File "/opt/virtualenvs/python3/lib/python3.8/site-packages/django/urls/resolvers.py", line 588, in url_patterns
    patterns = getattr(self.urlconf_module, "urlpatterns", self.urlconf_module)
  File "/opt/virtualenvs/python3/lib/python3.8/site-packages/django/utils/functional.py", line 48, in __get__
    res = instance.__dict__[self.name] = self.func(instance)
  File "/opt/virtualenvs/python3/lib/python3.8/site-packages/django/urls/resolvers.py", line 581, in urlconf_module
    return import_module(self.urlconf_name)
  File "/usr/lib/python3.8/importlib/__init__.py", line 127, in import_module
    return _bootstrap._gcd_import(name[level:], package, level)
  File "<frozen importlib._bootstrap>", line 1014, in _gcd_import
  File "<frozen importlib._bootstrap>", line 991, in _find_and_load
  File "<frozen importlib._bootstrap>", line 975, in _find_and_load_unlocked
  File "<frozen importlib._bootstrap>", line 671, in _load_unlocked
  File "<frozen importlib._bootstrap_external>", line 848, in exec_module
  File "<frozen importlib._bootstrap>", line 219, in _call_with_frames_removed
  File "/home/runner/wws/mysite/urls.py", line 18, in <module>
    import home.views
  File "/home/runner/wws/home/views.py", line 3, in <module>
    from django.backends.base.SessionBase import clear_expired
ModuleNotFoundError: No module named 'django.backends'

During handling of the above exception, another exception occurred:

Traceback (most recent call last):
  File "/opt/virtualenvs/python3/lib/python3.8/site-packages/django/core/handlers/exception.py", line 34, in inner
    response = get_response(request)
  File "/opt/virtualenvs/python3/lib/python3.8/site-packages/django/utils/deprecation.py", line 94, in __call__
    response = response or self.get_response(request)
  File "/opt/virtualenvs/python3/lib/python3.8/site-packages/django/core/handlers/exception.py", line 36, in inner
    response = response_for_exception(request, exc)
  File "/opt/virtualenvs/python3/lib/python3.8/site-packages/django/core/handlers/exception.py", line 90, in response_for_exception
    response = handle_uncaught_exception(request, get_resolver(get_urlconf()), sys.exc_info())
  File "/opt/virtualenvs/python3/lib/python3.8/site-packages/django/core/handlers/exception.py", line 128, in handle_uncaught_exception
    callback, param_dict = resolver.resolve_error_handler(500)
  File "/opt/virtualenvs/python3/lib/python3.8/site-packages/django/urls/resolvers.py", line 601, in resolve_error_handler
    callback = getattr(self.urlconf_module, 'handler%s' % view_type, None)
  File "/opt/virtualenvs/python3/lib/python3.8/site-packages/django/utils/functional.py", line 48, in __get__
    res = instance.__dict__[self.name] = self.func(instance)
  File "/opt/virtualenvs/python3/lib/python3.8/site-packages/django/urls/resolvers.py", line 581, in urlconf_module
    return import_module(self.urlconf_name)
  File "/usr/lib/python3.8/importlib/__init__.py", line 127, in import_module
    return _bootstrap._gcd_import(name[level:], package, level)
  File "<frozen importlib._bootstrap>", line 1014, in _gcd_import
  File "<frozen importlib._bootstrap>", line 991, in _find_and_load
  File "<frozen importlib._bootstrap>", line 975, in _find_and_load_unlocked
  File "<frozen importlib._bootstrap>", line 671, in _load_unlocked
  File "<frozen importlib._bootstrap_external>", line 848, in exec_module
  File "<frozen importlib._bootstrap>", line 219, in _call_with_frames_removed
  File "/home/runner/wws/mysite/urls.py", line 18, in <module>
    import home.views
  File "/home/runner/wws/home/views.py", line 3, in <module>
    from django.backends.base.SessionBase import clear_expired
ModuleNotFoundError: No module named 'django.backends'

During handling of the above exception, another exception occurred:

Traceback (most recent call last):
  File "/opt/virtualenvs/python3/lib/python3.8/site-packages/django/core/handlers/exception.py", line 34, in inner
    response = get_response(request)
  File "/opt/virtualenvs/python3/lib/python3.8/site-packages/django/utils/deprecation.py", line 94, in __call__
    response = response or self.get_response(request)
  File "/opt/virtualenvs/python3/lib/python3.8/site-packages/django/core/handlers/exception.py", line 36, in inner
    response = response_for_exception(request, exc)
  File "/opt/virtualenvs/python3/lib/python3.8/site-packages/django/core/handlers/exception.py", line 90, in response_for_exception
    response = handle_uncaught_exception(request, get_resolver(get_urlconf()), sys.exc_info())
  File "/opt/virtualenvs/python3/lib/python3.8/site-packages/django/core/handlers/exception.py", line 128, in handle_uncaught_exception
    callback, param_dict = resolver.resolve_error_handler(500)
  File "/opt/virtualenvs/python3/lib/python3.8/site-packages/django/urls/resolvers.py", line 601, in resolve_error_handler
    callback = getattr(self.urlconf_module, 'handler%s' % view_type, None)
  File "/opt/virtualenvs/python3/lib/python3.8/site-packages/django/utils/functional.py", line 48, in __get__
    res = instance.__dict__[self.name] = self.func(instance)
  File "/opt/virtualenvs/python3/lib/python3.8/site-packages/django/urls/resolvers.py", line 581, in urlconf_module
    return import_module(self.urlconf_name)
  File "/usr/lib/python3.8/importlib/__init__.py", line 127, in import_module
    return _bootstrap._gcd_import(name[level:], package, level)
  File "<frozen importlib._bootstrap>", line 1014, in _gcd_import
  File "<frozen importlib._bootstrap>", line 991, in _find_and_load
  File "<frozen importlib._bootstrap>", line 975, in _find_and_load_unlocked
  File "<frozen importlib._bootstrap>", line 671, in _load_unlocked
  File "<frozen importlib._bootstrap_external>", line 848, in exec_module
  File "<frozen importlib._bootstrap>", line 219, in _call_with_frames_removed
  File "/home/runner/wws/mysite/urls.py", line 18, in <module>
    import home.views
  File "/home/runner/wws/home/views.py", line 3, in <module>
    from django.backends.base.SessionBase import clear_expired
ModuleNotFoundError: No module named 'django.backends'

During handling of the above exception, another exception occurred:

Traceback (most recent call last):
  File "/opt/virtualenvs/python3/lib/python3.8/site-packages/gunicorn/workers/sync.py", line 136, in handle
    self.handle_request(listener, req, client, addr)
  File "/opt/virtualenvs/python3/lib/python3.8/site-packages/gunicorn/workers/sync.py", line 179, in handle_request
    respiter = self.wsgi(environ, resp.start_response)
  File "/opt/virtualenvs/python3/lib/python3.8/site-packages/whitenoise/base.py", line 85, in __call__
    return self.application(environ, start_response)
  File "/opt/virtualenvs/python3/lib/python3.8/site-packages/django/core/handlers/wsgi.py", line 133, in __call__
    response = self.get_response(request)
  File "/opt/virtualenvs/python3/lib/python3.8/site-packages/django/core/handlers/base.py", line 75, in get_response
    response = self._middleware_chain(request)
  File "/opt/virtualenvs/python3/lib/python3.8/site-packages/django/core/handlers/exception.py", line 36, in inner
    response = response_for_exception(request, exc)
  File "/opt/virtualenvs/python3/lib/python3.8/site-packages/django/core/handlers/exception.py", line 90, in response_for_exception
    response = handle_uncaught_exception(request, get_resolver(get_urlconf()), sys.exc_info())
  File "/opt/virtualenvs/python3/lib/python3.8/site-packages/django/core/handlers/exception.py", line 128, in handle_uncaught_exception
    callback, param_dict = resolver.resolve_error_handler(500)
  File "/opt/virtualenvs/python3/lib/python3.8/site-packages/django/urls/resolvers.py", line 601, in resolve_error_handler
    callback = getattr(self.urlconf_module, 'handler%s' % view_type, None)
  File "/opt/virtualenvs/python3/lib/python3.8/site-packages/django/utils/functional.py", line 48, in __get__
    res = instance.__dict__[self.name] = self.func(instance)
  File "/opt/virtualenvs/python3/lib/python3.8/site-packages/django/urls/resolvers.py", line 581, in urlconf_module
    return import_module(self.urlconf_name)
  File "/usr/lib/python3.8/importlib/__init__.py", line 127, in import_module
    return _bootstrap._gcd_import(name[level:], package, level)
  File "<frozen importlib._bootstrap>", line 1014, in _gcd_import
  File "<frozen importlib._bootstrap>", line 991, in _find_and_load
  File "<frozen importlib._bootstrap>", line 975, in _find_and_load_unlocked
  File "<frozen importlib._bootstrap>", line 671, in _load_unlocked
  File "<frozen importlib._bootstrap_external>", line 848, in exec_module
  File "<frozen importlib._bootstrap>", line 219, in _call_with_frames_removed
  File "/home/runner/wws/mysite/urls.py", line 18, in <module>
    import home.views
  File "/home/runner/wws/home/views.py", line 3, in <module>
    from django.backends.base.SessionBase import clear_expired
ModuleNotFoundError: No module named 'django.backends'
[2021-09-06 07:51:20 +0000] [2164] [INFO] Worker exiting (pid: 2164)
[2021-09-06 07:51:20 +0000] [2157] [INFO] Handling signal: term
[2021-09-06 07:51:20 +0000] [2157] [WARNING] Worker with pid 2164 was terminated due to signal 15
[2021-09-06 07:51:20 +0000] [2157] [INFO] Shutting down: Master
[2021-09-06 07:51:21 +0000] [2218] [INFO] Starting gunicorn 20.1.0
[2021-09-06 07:51:21 +0000] [2218] [INFO] Listening at: http://0.0.0.0:8080 (2218)
[2021-09-06 07:51:21 +0000] [2218] [INFO] Using worker: sync
[2021-09-06 07:51:21 +0000] [2228] [INFO] Booting worker with pid: 2228
[2021-09-06 07:51:22 +0000] [2228] [ERROR] Error handling request /
Traceback (most recent call last):
  File "/opt/virtualenvs/python3/lib/python3.8/site-packages/django/core/handlers/exception.py", line 34, in inner
    response = get_response(request)
  File "/opt/virtualenvs/python3/lib/python3.8/site-packages/django/core/handlers/base.py", line 100, in _get_response
    resolver_match = resolver.resolve(request.path_info)
  File "/opt/virtualenvs/python3/lib/python3.8/site-packages/django/urls/resolvers.py", line 544, in resolve
    for pattern in self.url_patterns:
  File "/opt/virtualenvs/python3/lib/python3.8/site-packages/django/utils/functional.py", line 48, in __get__
    res = instance.__dict__[self.name] = self.func(instance)
  File "/opt/virtualenvs/python3/lib/python3.8/site-packages/django/urls/resolvers.py", line 588, in url_patterns
    patterns = getattr(self.urlconf_module, "urlpatterns", self.urlconf_module)
  File "/opt/virtualenvs/python3/lib/python3.8/site-packages/django/utils/functional.py", line 48, in __get__
    res = instance.__dict__[self.name] = self.func(instance)
  File "/opt/virtualenvs/python3/lib/python3.8/site-packages/django/urls/resolvers.py", line 581, in urlconf_module
    return import_module(self.urlconf_name)
  File "/usr/lib/python3.8/importlib/__init__.py", line 127, in import_module
    return _bootstrap._gcd_import(name[level:], package, level)
  File "<frozen importlib._bootstrap>", line 1014, in _gcd_import
  File "<frozen importlib._bootstrap>", line 991, in _find_and_load
  File "<frozen importlib._bootstrap>", line 975, in _find_and_load_unlocked
  File "<frozen importlib._bootstrap>", line 671, in _load_unlocked
  File "<frozen importlib._bootstrap_external>", line 848, in exec_module
  File "<frozen importlib._bootstrap>", line 219, in _call_with_frames_removed
  File "/home/runner/wws/mysite/urls.py", line 18, in <module>
    import home.views
  File "/home/runner/wws/home/views.py", line 3, in <module>
    from django.backends.base.SessionBase import clear_expired
ModuleNotFoundError: No module named 'django.backends'

During handling of the above exception, another exception occurred:

Traceback (most recent call last):
  File "/opt/virtualenvs/python3/lib/python3.8/site-packages/django/core/handlers/exception.py", line 34, in inner
    response = get_response(request)
  File "/opt/virtualenvs/python3/lib/python3.8/site-packages/django/utils/deprecation.py", line 94, in __call__
    response = response or self.get_response(request)
  File "/opt/virtualenvs/python3/lib/python3.8/site-packages/django/core/handlers/exception.py", line 36, in inner
    response = response_for_exception(request, exc)
  File "/opt/virtualenvs/python3/lib/python3.8/site-packages/django/core/handlers/exception.py", line 90, in response_for_exception
    response = handle_uncaught_exception(request, get_resolver(get_urlconf()), sys.exc_info())
  File "/opt/virtualenvs/python3/lib/python3.8/site-packages/django/core/handlers/exception.py", line 128, in handle_uncaught_exception
    callback, param_dict = resolver.resolve_error_handler(500)
  File "/opt/virtualenvs/python3/lib/python3.8/site-packages/django/urls/resolvers.py", line 601, in resolve_error_handler
    callback = getattr(self.urlconf_module, 'handler%s' % view_type, None)
  File "/opt/virtualenvs/python3/lib/python3.8/site-packages/django/utils/functional.py", line 48, in __get__
    res = instance.__dict__[self.name] = self.func(instance)
  File "/opt/virtualenvs/python3/lib/python3.8/site-packages/django/urls/resolvers.py", line 581, in urlconf_module
    return import_module(self.urlconf_name)
  File "/usr/lib/python3.8/importlib/__init__.py", line 127, in import_module
    return _bootstrap._gcd_import(name[level:], package, level)
  File "<frozen importlib._bootstrap>", line 1014, in _gcd_import
  File "<frozen importlib._bootstrap>", line 991, in _find_and_load
  File "<frozen importlib._bootstrap>", line 975, in _find_and_load_unlocked
  File "<frozen importlib._bootstrap>", line 671, in _load_unlocked
  File "<frozen importlib._bootstrap_external>", line 848, in exec_module
  File "<frozen importlib._bootstrap>", line 219, in _call_with_frames_removed
  File "/home/runner/wws/mysite/urls.py", line 18, in <module>
    import home.views
  File "/home/runner/wws/home/views.py", line 3, in <module>
    from django.backends.base.SessionBase import clear_expired
ModuleNotFoundError: No module named 'django.backends'

During handling of the above exception, another exception occurred:

Traceback (most recent call last):
  File "/opt/virtualenvs/python3/lib/python3.8/site-packages/django/core/handlers/exception.py", line 34, in inner
    response = get_response(request)
  File "/opt/virtualenvs/python3/lib/python3.8/site-packages/django/utils/deprecation.py", line 94, in __call__
    response = response or self.get_response(request)
  File "/opt/virtualenvs/python3/lib/python3.8/site-packages/django/core/handlers/exception.py", line 36, in inner
    response = response_for_exception(request, exc)
  File "/opt/virtualenvs/python3/lib/python3.8/site-packages/django/core/handlers/exception.py", line 90, in response_for_exception
    response = handle_uncaught_exception(request, get_resolver(get_urlconf()), sys.exc_info())
  File "/opt/virtualenvs/python3/lib/python3.8/site-packages/django/core/handlers/exception.py", line 128, in handle_uncaught_exception
    callback, param_dict = resolver.resolve_error_handler(500)
  File "/opt/virtualenvs/python3/lib/python3.8/site-packages/django/urls/resolvers.py", line 601, in resolve_error_handler
    callback = getattr(self.urlconf_module, 'handler%s' % view_type, None)
  File "/opt/virtualenvs/python3/lib/python3.8/site-packages/django/utils/functional.py", line 48, in __get__
    res = instance.__dict__[self.name] = self.func(instance)
  File "/opt/virtualenvs/python3/lib/python3.8/site-packages/django/urls/resolvers.py", line 581, in urlconf_module
    return import_module(self.urlconf_name)
  File "/usr/lib/python3.8/importlib/__init__.py", line 127, in import_module
    return _bootstrap._gcd_import(name[level:], package, level)
  File "<frozen importlib._bootstrap>", line 1014, in _gcd_import
  File "<frozen importlib._bootstrap>", line 991, in _find_and_load
  File "<frozen importlib._bootstrap>", line 975, in _find_and_load_unlocked
  File "<frozen importlib._bootstrap>", line 671, in _load_unlocked
  File "<frozen importlib._bootstrap_external>", line 848, in exec_module
  File "<frozen importlib._bootstrap>", line 219, in _call_with_frames_removed
  File "/home/runner/wws/mysite/urls.py", line 18, in <module>
    import home.views
  File "/home/runner/wws/home/views.py", line 3, in <module>
    from django.backends.base.SessionBase import clear_expired
ModuleNotFoundError: No module named 'django.backends'

During handling of the above exception, another exception occurred:

Traceback (most recent call last):
  File "/opt/virtualenvs/python3/lib/python3.8/site-packages/django/core/handlers/exception.py", line 34, in inner
    response = get_response(request)
  File "/opt/virtualenvs/python3/lib/python3.8/site-packages/django/utils/deprecation.py", line 94, in __call__
    response = response or self.get_response(request)
  File "/opt/virtualenvs/python3/lib/python3.8/site-packages/django/core/handlers/exception.py", line 36, in inner
    response = response_for_exception(request, exc)
  File "/opt/virtualenvs/python3/lib/python3.8/site-packages/django/core/handlers/exception.py", line 90, in response_for_exception
    response = handle_uncaught_exception(request, get_resolver(get_urlconf()), sys.exc_info())
  File "/opt/virtualenvs/python3/lib/python3.8/site-packages/django/core/handlers/exception.py", line 128, in handle_uncaught_exception
    callback, param_dict = resolver.resolve_error_handler(500)
  File "/opt/virtualenvs/python3/lib/python3.8/site-packages/django/urls/resolvers.py", line 601, in resolve_error_handler
    callback = getattr(self.urlconf_module, 'handler%s' % view_type, None)
  File "/opt/virtualenvs/python3/lib/python3.8/site-packages/django/utils/functional.py", line 48, in __get__
    res = instance.__dict__[self.name] = self.func(instance)
  File "/opt/virtualenvs/python3/lib/python3.8/site-packages/django/urls/resolvers.py", line 581, in urlconf_module
    return import_module(self.urlconf_name)
  File "/usr/lib/python3.8/importlib/__init__.py", line 127, in import_module
    return _bootstrap._gcd_import(name[level:], package, level)
  File "<frozen importlib._bootstrap>", line 1014, in _gcd_import
  File "<frozen importlib._bootstrap>", line 991, in _find_and_load
  File "<frozen importlib._bootstrap>", line 975, in _find_and_load_unlocked
  File "<frozen importlib._bootstrap>", line 671, in _load_unlocked
  File "<frozen importlib._bootstrap_external>", line 848, in exec_module
  File "<frozen importlib._bootstrap>", line 219, in _call_with_frames_removed
  File "/home/runner/wws/mysite/urls.py", line 18, in <module>
    import home.views
  File "/home/runner/wws/home/views.py", line 3, in <module>
    from django.backends.base.SessionBase import clear_expired
ModuleNotFoundError: No module named 'django.backends'

During handling of the above exception, another exception occurred:

Traceback (most recent call last):
  File "/opt/virtualenvs/python3/lib/python3.8/site-packages/django/core/handlers/exception.py", line 34, in inner
    response = get_response(request)
  File "/opt/virtualenvs/python3/lib/python3.8/site-packages/django/utils/deprecation.py", line 94, in __call__
    response = response or self.get_response(request)
  File "/opt/virtualenvs/python3/lib/python3.8/site-packages/django/core/handlers/exception.py", line 36, in inner
    response = response_for_exception(request, exc)
  File "/opt/virtualenvs/python3/lib/python3.8/site-packages/django/core/handlers/exception.py", line 90, in response_for_exception
    response = handle_uncaught_exception(request, get_resolver(get_urlconf()), sys.exc_info())
  File "/opt/virtualenvs/python3/lib/python3.8/site-packages/django/core/handlers/exception.py", line 128, in handle_uncaught_exception
    callback, param_dict = resolver.resolve_error_handler(500)
  File "/opt/virtualenvs/python3/lib/python3.8/site-packages/django/urls/resolvers.py", line 601, in resolve_error_handler
    callback = getattr(self.urlconf_module, 'handler%s' % view_type, None)
  File "/opt/virtualenvs/python3/lib/python3.8/site-packages/django/utils/functional.py", line 48, in __get__
    res = instance.__dict__[self.name] = self.func(instance)
  File "/opt/virtualenvs/python3/lib/python3.8/site-packages/django/urls/resolvers.py", line 581, in urlconf_module
    return import_module(self.urlconf_name)
  File "/usr/lib/python3.8/importlib/__init__.py", line 127, in import_module
    return _bootstrap._gcd_import(name[level:], package, level)
  File "<frozen importlib._bootstrap>", line 1014, in _gcd_import
  File "<frozen importlib._bootstrap>", line 991, in _find_and_load
  File "<frozen importlib._bootstrap>", line 975, in _find_and_load_unlocked
  File "<frozen importlib._bootstrap>", line 671, in _load_unlocked
  File "<frozen importlib._bootstrap_external>", line 848, in exec_module
  File "<frozen importlib._bootstrap>", line 219, in _call_with_frames_removed
  File "/home/runner/wws/mysite/urls.py", line 18, in <module>
    import home.views
  File "/home/runner/wws/home/views.py", line 3, in <module>
    from django.backends.base.SessionBase import clear_expired
ModuleNotFoundError: No module named 'django.backends'

During handling of the above exception, another exception occurred:

Traceback (most recent call last):
  File "/opt/virtualenvs/python3/lib/python3.8/site-packages/django/core/handlers/exception.py", line 34, in inner
    response = get_response(request)
  File "/opt/virtualenvs/python3/lib/python3.8/site-packages/django/utils/deprecation.py", line 94, in __call__
    response = response or self.get_response(request)
  File "/opt/virtualenvs/python3/lib/python3.8/site-packages/django/core/handlers/exception.py", line 36, in inner
    response = response_for_exception(request, exc)
  File "/opt/virtualenvs/python3/lib/python3.8/site-packages/django/core/handlers/exception.py", line 90, in response_for_exception
    response = handle_uncaught_exception(request, get_resolver(get_urlconf()), sys.exc_info())
  File "/opt/virtualenvs/python3/lib/python3.8/site-packages/django/core/handlers/exception.py", line 128, in handle_uncaught_exception
    callback, param_dict = resolver.resolve_error_handler(500)
  File "/opt/virtualenvs/python3/lib/python3.8/site-packages/django/urls/resolvers.py", line 601, in resolve_error_handler
    callback = getattr(self.urlconf_module, 'handler%s' % view_type, None)
  File "/opt/virtualenvs/python3/lib/python3.8/site-packages/django/utils/functional.py", line 48, in __get__
    res = instance.__dict__[self.name] = self.func(instance)
  File "/opt/virtualenvs/python3/lib/python3.8/site-packages/django/urls/resolvers.py", line 581, in urlconf_module
    return import_module(self.urlconf_name)
  File "/usr/lib/python3.8/importlib/__init__.py", line 127, in import_module
    return _bootstrap._gcd_import(name[level:], package, level)
  File "<frozen importlib._bootstrap>", line 1014, in _gcd_import
  File "<frozen importlib._bootstrap>", line 991, in _find_and_load
  File "<frozen importlib._bootstrap>", line 975, in _find_and_load_unlocked
  File "<frozen importlib._bootstrap>", line 671, in _load_unlocked
  File "<frozen importlib._bootstrap_external>", line 848, in exec_module
  File "<frozen importlib._bootstrap>", line 219, in _call_with_frames_removed
  File "/home/runner/wws/mysite/urls.py", line 18, in <module>
    import home.views
  File "/home/runner/wws/home/views.py", line 3, in <module>
    from django.backends.base.SessionBase import clear_expired
ModuleNotFoundError: No module named 'django.backends'

During handling of the above exception, another exception occurred:

Traceback (most recent call last):
  File "/opt/virtualenvs/python3/lib/python3.8/site-packages/django/core/handlers/exception.py", line 34, in inner
    response = get_response(request)
  File "/opt/virtualenvs/python3/lib/python3.8/site-packages/django/utils/deprecation.py", line 94, in __call__
    response = response or self.get_response(request)
  File "/opt/virtualenvs/python3/lib/python3.8/site-packages/django/core/handlers/exception.py", line 36, in inner
    response = response_for_exception(request, exc)
  File "/opt/virtualenvs/python3/lib/python3.8/site-packages/django/core/handlers/exception.py", line 90, in response_for_exception
    response = handle_uncaught_exception(request, get_resolver(get_urlconf()), sys.exc_info())
  File "/opt/virtualenvs/python3/lib/python3.8/site-packages/django/core/handlers/exception.py", line 128, in handle_uncaught_exception
    callback, param_dict = resolver.resolve_error_handler(500)
  File "/opt/virtualenvs/python3/lib/python3.8/site-packages/django/urls/resolvers.py", line 601, in resolve_error_handler
    callback = getattr(self.urlconf_module, 'handler%s' % view_type, None)
  File "/opt/virtualenvs/python3/lib/python3.8/site-packages/django/utils/functional.py", line 48, in __get__
    res = instance.__dict__[self.name] = self.func(instance)
  File "/opt/virtualenvs/python3/lib/python3.8/site-packages/django/urls/resolvers.py", line 581, in urlconf_module
    return import_module(self.urlconf_name)
  File "/usr/lib/python3.8/importlib/__init__.py", line 127, in import_module
    return _bootstrap._gcd_import(name[level:], package, level)
  File "<frozen importlib._bootstrap>", line 1014, in _gcd_import
  File "<frozen importlib._bootstrap>", line 991, in _find_and_load
  File "<frozen importlib._bootstrap>", line 975, in _find_and_load_unlocked
  File "<frozen importlib._bootstrap>", line 671, in _load_unlocked
  File "<frozen importlib._bootstrap_external>", line 848, in exec_module
  File "<frozen importlib._bootstrap>", line 219, in _call_with_frames_removed
  File "/home/runner/wws/mysite/urls.py", line 18, in <module>
    import home.views
  File "/home/runner/wws/home/views.py", line 3, in <module>
    from django.backends.base.SessionBase import clear_expired
ModuleNotFoundError: No module named 'django.backends'

During handling of the above exception, another exception occurred:

Traceback (most recent call last):
  File "/opt/virtualenvs/python3/lib/python3.8/site-packages/django/core/handlers/exception.py", line 34, in inner
    response = get_response(request)
  File "/opt/virtualenvs/python3/lib/python3.8/site-packages/django/utils/deprecation.py", line 94, in __call__
    response = response or self.get_response(request)
  File "/opt/virtualenvs/python3/lib/python3.8/site-packages/django/core/handlers/exception.py", line 36, in inner
    response = response_for_exception(request, exc)
  File "/opt/virtualenvs/python3/lib/python3.8/site-packages/django/core/handlers/exception.py", line 90, in response_for_exception
    response = handle_uncaught_exception(request, get_resolver(get_urlconf()), sys.exc_info())
  File "/opt/virtualenvs/python3/lib/python3.8/site-packages/django/core/handlers/exception.py", line 128, in handle_uncaught_exception
    callback, param_dict = resolver.resolve_error_handler(500)
  File "/opt/virtualenvs/python3/lib/python3.8/site-packages/django/urls/resolvers.py", line 601, in resolve_error_handler
    callback = getattr(self.urlconf_module, 'handler%s' % view_type, None)
  File "/opt/virtualenvs/python3/lib/python3.8/site-packages/django/utils/functional.py", line 48, in __get__
    res = instance.__dict__[self.name] = self.func(instance)
  File "/opt/virtualenvs/python3/lib/python3.8/site-packages/django/urls/resolvers.py", line 581, in urlconf_module
    return import_module(self.urlconf_name)
  File "/usr/lib/python3.8/importlib/__init__.py", line 127, in import_module
    return _bootstrap._gcd_import(name[level:], package, level)
  File "<frozen importlib._bootstrap>", line 1014, in _gcd_import
  File "<frozen importlib._bootstrap>", line 991, in _find_and_load
  File "<frozen importlib._bootstrap>", line 975, in _find_and_load_unlocked
  File "<frozen importlib._bootstrap>", line 671, in _load_unlocked
  File "<frozen importlib._bootstrap_external>", line 848, in exec_module
  File "<frozen importlib._bootstrap>", line 219, in _call_with_frames_removed
  File "/home/runner/wws/mysite/urls.py", line 18, in <module>
    import home.views
  File "/home/runner/wws/home/views.py", line 3, in <module>
    from django.backends.base.SessionBase import clear_expired
ModuleNotFoundError: No module named 'django.backends'

During handling of the above exception, another exception occurred:

Traceback (most recent call last):
  File "/opt/virtualenvs/python3/lib/python3.8/site-packages/gunicorn/workers/sync.py", line 136, in handle
    self.handle_request(listener, req, client, addr)
  File "/opt/virtualenvs/python3/lib/python3.8/site-packages/gunicorn/workers/sync.py", line 179, in handle_request
    respiter = self.wsgi(environ, resp.start_response)
  File "/opt/virtualenvs/python3/lib/python3.8/site-packages/whitenoise/base.py", line 85, in __call__
    return self.application(environ, start_response)
  File "/opt/virtualenvs/python3/lib/python3.8/site-packages/django/core/handlers/wsgi.py", line 133, in __call__
    response = self.get_response(request)
  File "/opt/virtualenvs/python3/lib/python3.8/site-packages/django/core/handlers/base.py", line 75, in get_response
    response = self._middleware_chain(request)
  File "/opt/virtualenvs/python3/lib/python3.8/site-packages/django/core/handlers/exception.py", line 36, in inner
    response = response_for_exception(request, exc)
  File "/opt/virtualenvs/python3/lib/python3.8/site-packages/django/core/handlers/exception.py", line 90, in response_for_exception
    response = handle_uncaught_exception(request, get_resolver(get_urlconf()), sys.exc_info())
  File "/opt/virtualenvs/python3/lib/python3.8/site-packages/django/core/handlers/exception.py", line 128, in handle_uncaught_exception
    callback, param_dict = resolver.resolve_error_handler(500)
  File "/opt/virtualenvs/python3/lib/python3.8/site-packages/django/urls/resolvers.py", line 601, in resolve_error_handler
    callback = getattr(self.urlconf_module, 'handler%s' % view_type, None)
  File "/opt/virtualenvs/python3/lib/python3.8/site-packages/django/utils/functional.py", line 48, in __get__
    res = instance.__dict__[self.name] = self.func(instance)
  File "/opt/virtualenvs/python3/lib/python3.8/site-packages/django/urls/resolvers.py", line 581, in urlconf_module
    return import_module(self.urlconf_name)
  File "/usr/lib/python3.8/importlib/__init__.py", line 127, in import_module
    return _bootstrap._gcd_import(name[level:], package, level)
  File "<frozen importlib._bootstrap>", line 1014, in _gcd_import
  File "<frozen importlib._bootstrap>", line 991, in _find_and_load
  File "<frozen importlib._bootstrap>", line 975, in _find_and_load_unlocked
  File "<frozen importlib._bootstrap>", line 671, in _load_unlocked
  File "<frozen importlib._bootstrap_external>", line 848, in exec_module
  File "<frozen importlib._bootstrap>", line 219, in _call_with_frames_removed
  File "/home/runner/wws/mysite/urls.py", line 18, in <module>
    import home.views
  File "/home/runner/wws/home/views.py", line 3, in <module>
    from django.backends.base.SessionBase import clear_expired
ModuleNotFoundError: No module named 'django.backends'
[2021-09-06 07:51:34 +0000] [2228] [ERROR] Error handling request /
Traceback (most recent call last):
  File "/opt/virtualenvs/python3/lib/python3.8/site-packages/django/core/handlers/exception.py", line 34, in inner
    response = get_response(request)
  File "/opt/virtualenvs/python3/lib/python3.8/site-packages/django/core/handlers/base.py", line 100, in _get_response
    resolver_match = resolver.resolve(request.path_info)
  File "/opt/virtualenvs/python3/lib/python3.8/site-packages/django/urls/resolvers.py", line 544, in resolve
    for pattern in self.url_patterns:
  File "/opt/virtualenvs/python3/lib/python3.8/site-packages/django/utils/functional.py", line 48, in __get__
    res = instance.__dict__[self.name] = self.func(instance)
  File "/opt/virtualenvs/python3/lib/python3.8/site-packages/django/urls/resolvers.py", line 588, in url_patterns
    patterns = getattr(self.urlconf_module, "urlpatterns", self.urlconf_module)
  File "/opt/virtualenvs/python3/lib/python3.8/site-packages/django/utils/functional.py", line 48, in __get__
    res = instance.__dict__[self.name] = self.func(instance)
  File "/opt/virtualenvs/python3/lib/python3.8/site-packages/django/urls/resolvers.py", line 581, in urlconf_module
    return import_module(self.urlconf_name)
  File "/usr/lib/python3.8/importlib/__init__.py", line 127, in import_module
    return _bootstrap._gcd_import(name[level:], package, level)
  File "<frozen importlib._bootstrap>", line 1014, in _gcd_import
  File "<frozen importlib._bootstrap>", line 991, in _find_and_load
  File "<frozen importlib._bootstrap>", line 975, in _find_and_load_unlocked
  File "<frozen importlib._bootstrap>", line 671, in _load_unlocked
  File "<frozen importlib._bootstrap_external>", line 848, in exec_module
  File "<frozen importlib._bootstrap>", line 219, in _call_with_frames_removed
  File "/home/runner/wws/mysite/urls.py", line 18, in <module>
    import home.views
  File "/home/runner/wws/home/views.py", line 3, in <module>
    from django.backends.base.SessionBase import clear_expired
ModuleNotFoundError: No module named 'django.backends'

During handling of the above exception, another exception occurred:

Traceback (most recent call last):
  File "/opt/virtualenvs/python3/lib/python3.8/site-packages/django/core/handlers/exception.py", line 34, in inner
    response = get_response(request)
  File "/opt/virtualenvs/python3/lib/python3.8/site-packages/django/utils/deprecation.py", line 94, in __call__
    response = response or self.get_response(request)
  File "/opt/virtualenvs/python3/lib/python3.8/site-packages/django/core/handlers/exception.py", line 36, in inner
    response = response_for_exception(request, exc)
  File "/opt/virtualenvs/python3/lib/python3.8/site-packages/django/core/handlers/exception.py", line 90, in response_for_exception
    response = handle_uncaught_exception(request, get_resolver(get_urlconf()), sys.exc_info())
  File "/opt/virtualenvs/python3/lib/python3.8/site-packages/django/core/handlers/exception.py", line 128, in handle_uncaught_exception
    callback, param_dict = resolver.resolve_error_handler(500)
  File "/opt/virtualenvs/python3/lib/python3.8/site-packages/django/urls/resolvers.py", line 601, in resolve_error_handler
    callback = getattr(self.urlconf_module, 'handler%s' % view_type, None)
  File "/opt/virtualenvs/python3/lib/python3.8/site-packages/django/utils/functional.py", line 48, in __get__
    res = instance.__dict__[self.name] = self.func(instance)
  File "/opt/virtualenvs/python3/lib/python3.8/site-packages/django/urls/resolvers.py", line 581, in urlconf_module
    return import_module(self.urlconf_name)
  File "/usr/lib/python3.8/importlib/__init__.py", line 127, in import_module
    return _bootstrap._gcd_import(name[level:], package, level)
  File "<frozen importlib._bootstrap>", line 1014, in _gcd_import
  File "<frozen importlib._bootstrap>", line 991, in _find_and_load
  File "<frozen importlib._bootstrap>", line 975, in _find_and_load_unlocked
  File "<frozen importlib._bootstrap>", line 671, in _load_unlocked
  File "<frozen importlib._bootstrap_external>", line 848, in exec_module
  File "<frozen importlib._bootstrap>", line 219, in _call_with_frames_removed
  File "/home/runner/wws/mysite/urls.py", line 18, in <module>
    import home.views
  File "/home/runner/wws/home/views.py", line 3, in <module>
    from django.backends.base.SessionBase import clear_expired
ModuleNotFoundError: No module named 'django.backends'

During handling of the above exception, another exception occurred:

Traceback (most recent call last):
  File "/opt/virtualenvs/python3/lib/python3.8/site-packages/django/core/handlers/exception.py", line 34, in inner
    response = get_response(request)
  File "/opt/virtualenvs/python3/lib/python3.8/site-packages/django/utils/deprecation.py", line 94, in __call__
    response = response or self.get_response(request)
  File "/opt/virtualenvs/python3/lib/python3.8/site-packages/django/core/handlers/exception.py", line 36, in inner
    response = response_for_exception(request, exc)
  File "/opt/virtualenvs/python3/lib/python3.8/site-packages/django/core/handlers/exception.py", line 90, in response_for_exception
    response = handle_uncaught_exception(request, get_resolver(get_urlconf()), sys.exc_info())
  File "/opt/virtualenvs/python3/lib/python3.8/site-packages/django/core/handlers/exception.py", line 128, in handle_uncaught_exception
    callback, param_dict = resolver.resolve_error_handler(500)
  File "/opt/virtualenvs/python3/lib/python3.8/site-packages/django/urls/resolvers.py", line 601, in resolve_error_handler
    callback = getattr(self.urlconf_module, 'handler%s' % view_type, None)
  File "/opt/virtualenvs/python3/lib/python3.8/site-packages/django/utils/functional.py", line 48, in __get__
    res = instance.__dict__[self.name] = self.func(instance)
  File "/opt/virtualenvs/python3/lib/python3.8/site-packages/django/urls/resolvers.py", line 581, in urlconf_module
    return import_module(self.urlconf_name)
  File "/usr/lib/python3.8/importlib/__init__.py", line 127, in import_module
    return _bootstrap._gcd_import(name[level:], package, level)
  File "<frozen importlib._bootstrap>", line 1014, in _gcd_import
  File "<frozen importlib._bootstrap>", line 991, in _find_and_load
  File "<frozen importlib._bootstrap>", line 975, in _find_and_load_unlocked
  File "<frozen importlib._bootstrap>", line 671, in _load_unlocked
  File "<frozen importlib._bootstrap_external>", line 848, in exec_module
  File "<frozen importlib._bootstrap>", line 219, in _call_with_frames_removed
  File "/home/runner/wws/mysite/urls.py", line 18, in <module>
    import home.views
  File "/home/runner/wws/home/views.py", line 3, in <module>
    from django.backends.base.SessionBase import clear_expired
ModuleNotFoundError: No module named 'django.backends'

During handling of the above exception, another exception occurred:

Traceback (most recent call last):
  File "/opt/virtualenvs/python3/lib/python3.8/site-packages/django/core/handlers/exception.py", line 34, in inner
    response = get_response(request)
  File "/opt/virtualenvs/python3/lib/python3.8/site-packages/django/utils/deprecation.py", line 94, in __call__
    response = response or self.get_response(request)
  File "/opt/virtualenvs/python3/lib/python3.8/site-packages/django/core/handlers/exception.py", line 36, in inner
    response = response_for_exception(request, exc)
  File "/opt/virtualenvs/python3/lib/python3.8/site-packages/django/core/handlers/exception.py", line 90, in response_for_exception
    response = handle_uncaught_exception(request, get_resolver(get_urlconf()), sys.exc_info())
  File "/opt/virtualenvs/python3/lib/python3.8/site-packages/django/core/handlers/exception.py", line 128, in handle_uncaught_exception
    callback, param_dict = resolver.resolve_error_handler(500)
  File "/opt/virtualenvs/python3/lib/python3.8/site-packages/django/urls/resolvers.py", line 601, in resolve_error_handler
    callback = getattr(self.urlconf_module, 'handler%s' % view_type, None)
  File "/opt/virtualenvs/python3/lib/python3.8/site-packages/django/utils/functional.py", line 48, in __get__
    res = instance.__dict__[self.name] = self.func(instance)
  File "/opt/virtualenvs/python3/lib/python3.8/site-packages/django/urls/resolvers.py", line 581, in urlconf_module
    return import_module(self.urlconf_name)
  File "/usr/lib/python3.8/importlib/__init__.py", line 127, in import_module
    return _bootstrap._gcd_import(name[level:], package, level)
  File "<frozen importlib._bootstrap>", line 1014, in _gcd_import
  File "<frozen importlib._bootstrap>", line 991, in _find_and_load
  File "<frozen importlib._bootstrap>", line 975, in _find_and_load_unlocked
  File "<frozen importlib._bootstrap>", line 671, in _load_unlocked
  File "<frozen importlib._bootstrap_external>", line 848, in exec_module
  File "<frozen importlib._bootstrap>", line 219, in _call_with_frames_removed
  File "/home/runner/wws/mysite/urls.py", line 18, in <module>
    import home.views
  File "/home/runner/wws/home/views.py", line 3, in <module>
    from django.backends.base.SessionBase import clear_expired
ModuleNotFoundError: No module named 'django.backends'

During handling of the above exception, another exception occurred:

Traceback (most recent call last):
  File "/opt/virtualenvs/python3/lib/python3.8/site-packages/django/core/handlers/exception.py", line 34, in inner
    response = get_response(request)
  File "/opt/virtualenvs/python3/lib/python3.8/site-packages/django/utils/deprecation.py", line 94, in __call__
    response = response or self.get_response(request)
  File "/opt/virtualenvs/python3/lib/python3.8/site-packages/django/core/handlers/exception.py", line 36, in inner
    response = response_for_exception(request, exc)
  File "/opt/virtualenvs/python3/lib/python3.8/site-packages/django/core/handlers/exception.py", line 90, in response_for_exception
    response = handle_uncaught_exception(request, get_resolver(get_urlconf()), sys.exc_info())
  File "/opt/virtualenvs/python3/lib/python3.8/site-packages/django/core/handlers/exception.py", line 128, in handle_uncaught_exception
    callback, param_dict = resolver.resolve_error_handler(500)
  File "/opt/virtualenvs/python3/lib/python3.8/site-packages/django/urls/resolvers.py", line 601, in resolve_error_handler
    callback = getattr(self.urlconf_module, 'handler%s' % view_type, None)
  File "/opt/virtualenvs/python3/lib/python3.8/site-packages/django/utils/functional.py", line 48, in __get__
    res = instance.__dict__[self.name] = self.func(instance)
  File "/opt/virtualenvs/python3/lib/python3.8/site-packages/django/urls/resolvers.py", line 581, in urlconf_module
    return import_module(self.urlconf_name)
  File "/usr/lib/python3.8/importlib/__init__.py", line 127, in import_module
    return _bootstrap._gcd_import(name[level:], package, level)
  File "<frozen importlib._bootstrap>", line 1014, in _gcd_import
  File "<frozen importlib._bootstrap>", line 991, in _find_and_load
  File "<frozen importlib._bootstrap>", line 975, in _find_and_load_unlocked
  File "<frozen importlib._bootstrap>", line 671, in _load_unlocked
  File "<frozen importlib._bootstrap_external>", line 848, in exec_module
  File "<frozen importlib._bootstrap>", line 219, in _call_with_frames_removed
  File "/home/runner/wws/mysite/urls.py", line 18, in <module>
    import home.views
  File "/home/runner/wws/home/views.py", line 3, in <module>
    from django.backends.base.SessionBase import clear_expired
ModuleNotFoundError: No module named 'django.backends'

During handling of the above exception, another exception occurred:

Traceback (most recent call last):
  File "/opt/virtualenvs/python3/lib/python3.8/site-packages/django/core/handlers/exception.py", line 34, in inner
    response = get_response(request)
  File "/opt/virtualenvs/python3/lib/python3.8/site-packages/django/utils/deprecation.py", line 94, in __call__
    response = response or self.get_response(request)
  File "/opt/virtualenvs/python3/lib/python3.8/site-packages/django/core/handlers/exception.py", line 36, in inner
    response = response_for_exception(request, exc)
  File "/opt/virtualenvs/python3/lib/python3.8/site-packages/django/core/handlers/exception.py", line 90, in response_for_exception
    response = handle_uncaught_exception(request, get_resolver(get_urlconf()), sys.exc_info())
  File "/opt/virtualenvs/python3/lib/python3.8/site-packages/django/core/handlers/exception.py", line 128, in handle_uncaught_exception
    callback, param_dict = resolver.resolve_error_handler(500)
  File "/opt/virtualenvs/python3/lib/python3.8/site-packages/django/urls/resolvers.py", line 601, in resolve_error_handler
    callback = getattr(self.urlconf_module, 'handler%s' % view_type, None)
  File "/opt/virtualenvs/python3/lib/python3.8/site-packages/django/utils/functional.py", line 48, in __get__
    res = instance.__dict__[self.name] = self.func(instance)
  File "/opt/virtualenvs/python3/lib/python3.8/site-packages/django/urls/resolvers.py", line 581, in urlconf_module
    return import_module(self.urlconf_name)
  File "/usr/lib/python3.8/importlib/__init__.py", line 127, in import_module
    return _bootstrap._gcd_import(name[level:], package, level)
  File "<frozen importlib._bootstrap>", line 1014, in _gcd_import
  File "<frozen importlib._bootstrap>", line 991, in _find_and_load
  File "<frozen importlib._bootstrap>", line 975, in _find_and_load_unlocked
  File "<frozen importlib._bootstrap>", line 671, in _load_unlocked
  File "<frozen importlib._bootstrap_external>", line 848, in exec_module
  File "<frozen importlib._bootstrap>", line 219, in _call_with_frames_removed
  File "/home/runner/wws/mysite/urls.py", line 18, in <module>
    import home.views
  File "/home/runner/wws/home/views.py", line 3, in <module>
    from django.backends.base.SessionBase import clear_expired
ModuleNotFoundError: No module named 'django.backends'

During handling of the above exception, another exception occurred:

Traceback (most recent call last):
  File "/opt/virtualenvs/python3/lib/python3.8/site-packages/django/core/handlers/exception.py", line 34, in inner
    response = get_response(request)
  File "/opt/virtualenvs/python3/lib/python3.8/site-packages/django/utils/deprecation.py", line 94, in __call__
    response = response or self.get_response(request)
  File "/opt/virtualenvs/python3/lib/python3.8/site-packages/django/core/handlers/exception.py", line 36, in inner
    response = response_for_exception(request, exc)
  File "/opt/virtualenvs/python3/lib/python3.8/site-packages/django/core/handlers/exception.py", line 90, in response_for_exception
    response = handle_uncaught_exception(request, get_resolver(get_urlconf()), sys.exc_info())
  File "/opt/virtualenvs/python3/lib/python3.8/site-packages/django/core/handlers/exception.py", line 128, in handle_uncaught_exception
    callback, param_dict = resolver.resolve_error_handler(500)
  File "/opt/virtualenvs/python3/lib/python3.8/site-packages/django/urls/resolvers.py", line 601, in resolve_error_handler
    callback = getattr(self.urlconf_module, 'handler%s' % view_type, None)
  File "/opt/virtualenvs/python3/lib/python3.8/site-packages/django/utils/functional.py", line 48, in __get__
    res = instance.__dict__[self.name] = self.func(instance)
  File "/opt/virtualenvs/python3/lib/python3.8/site-packages/django/urls/resolvers.py", line 581, in urlconf_module
    return import_module(self.urlconf_name)
  File "/usr/lib/python3.8/importlib/__init__.py", line 127, in import_module
    return _bootstrap._gcd_import(name[level:], package, level)
  File "<frozen importlib._bootstrap>", line 1014, in _gcd_import
  File "<frozen importlib._bootstrap>", line 991, in _find_and_load
  File "<frozen importlib._bootstrap>", line 975, in _find_and_load_unlocked
  File "<frozen importlib._bootstrap>", line 671, in _load_unlocked
  File "<frozen importlib._bootstrap_external>", line 848, in exec_module
  File "<frozen importlib._bootstrap>", line 219, in _call_with_frames_removed
  File "/home/runner/wws/mysite/urls.py", line 18, in <module>
    import home.views
  File "/home/runner/wws/home/views.py", line 3, in <module>
    from django.backends.base.SessionBase import clear_expired
ModuleNotFoundError: No module named 'django.backends'

During handling of the above exception, another exception occurred:

Traceback (most recent call last):
  File "/opt/virtualenvs/python3/lib/python3.8/site-packages/django/core/handlers/exception.py", line 34, in inner
    response = get_response(request)
  File "/opt/virtualenvs/python3/lib/python3.8/site-packages/django/utils/deprecation.py", line 94, in __call__
    response = response or self.get_response(request)
  File "/opt/virtualenvs/python3/lib/python3.8/site-packages/django/core/handlers/exception.py", line 36, in inner
    response = response_for_exception(request, exc)
  File "/opt/virtualenvs/python3/lib/python3.8/site-packages/django/core/handlers/exception.py", line 90, in response_for_exception
    response = handle_uncaught_exception(request, get_resolver(get_urlconf()), sys.exc_info())
  File "/opt/virtualenvs/python3/lib/python3.8/site-packages/django/core/handlers/exception.py", line 128, in handle_uncaught_exception
    callback, param_dict = resolver.resolve_error_handler(500)
  File "/opt/virtualenvs/python3/lib/python3.8/site-packages/django/urls/resolvers.py", line 601, in resolve_error_handler
    callback = getattr(self.urlconf_module, 'handler%s' % view_type, None)
  File "/opt/virtualenvs/python3/lib/python3.8/site-packages/django/utils/functional.py", line 48, in __get__
    res = instance.__dict__[self.name] = self.func(instance)
  File "/opt/virtualenvs/python3/lib/python3.8/site-packages/django/urls/resolvers.py", line 581, in urlconf_module
    return import_module(self.urlconf_name)
  File "/usr/lib/python3.8/importlib/__init__.py", line 127, in import_module
    return _bootstrap._gcd_import(name[level:], package, level)
  File "<frozen importlib._bootstrap>", line 1014, in _gcd_import
  File "<frozen importlib._bootstrap>", line 991, in _find_and_load
  File "<frozen importlib._bootstrap>", line 975, in _find_and_load_unlocked
  File "<frozen importlib._bootstrap>", line 671, in _load_unlocked
  File "<frozen importlib._bootstrap_external>", line 848, in exec_module
  File "<frozen importlib._bootstrap>", line 219, in _call_with_frames_removed
  File "/home/runner/wws/mysite/urls.py", line 18, in <module>
    import home.views
  File "/home/runner/wws/home/views.py", line 3, in <module>
    from django.backends.base.SessionBase import clear_expired
ModuleNotFoundError: No module named 'django.backends'

During handling of the above exception, another exception occurred:

Traceback (most recent call last):
  File "/opt/virtualenvs/python3/lib/python3.8/site-packages/gunicorn/workers/sync.py", line 136, in handle
    self.handle_request(listener, req, client, addr)
  File "/opt/virtualenvs/python3/lib/python3.8/site-packages/gunicorn/workers/sync.py", line 179, in handle_request
    respiter = self.wsgi(environ, resp.start_response)
  File "/opt/virtualenvs/python3/lib/python3.8/site-packages/whitenoise/base.py", line 85, in __call__
    return self.application(environ, start_response)
  File "/opt/virtualenvs/python3/lib/python3.8/site-packages/django/core/handlers/wsgi.py", line 133, in __call__
    response = self.get_response(request)
  File "/opt/virtualenvs/python3/lib/python3.8/site-packages/django/core/handlers/base.py", line 75, in get_response
    response = self._middleware_chain(request)
  File "/opt/virtualenvs/python3/lib/python3.8/site-packages/django/core/handlers/exception.py", line 36, in inner
    response = response_for_exception(request, exc)
  File "/opt/virtualenvs/python3/lib/python3.8/site-packages/django/core/handlers/exception.py", line 90, in response_for_exception
    response = handle_uncaught_exception(request, get_resolver(get_urlconf()), sys.exc_info())
  File "/opt/virtualenvs/python3/lib/python3.8/site-packages/django/core/handlers/exception.py", line 128, in handle_uncaught_exception
    callback, param_dict = resolver.resolve_error_handler(500)
  File "/opt/virtualenvs/python3/lib/python3.8/site-packages/django/urls/resolvers.py", line 601, in resolve_error_handler
    callback = getattr(self.urlconf_module, 'handler%s' % view_type, None)
  File "/opt/virtualenvs/python3/lib/python3.8/site-packages/django/utils/functional.py", line 48, in __get__
    res = instance.__dict__[self.name] = self.func(instance)
  File "/opt/virtualenvs/python3/lib/python3.8/site-packages/django/urls/resolvers.py", line 581, in urlconf_module
    return import_module(self.urlconf_name)
  File "/usr/lib/python3.8/importlib/__init__.py", line 127, in import_module
    return _bootstrap._gcd_import(name[level:], package, level)
  File "<frozen importlib._bootstrap>", line 1014, in _gcd_import
  File "<frozen importlib._bootstrap>", line 991, in _find_and_load
  File "<frozen importlib._bootstrap>", line 975, in _find_and_load_unlocked
  File "<frozen importlib._bootstrap>", line 671, in _load_unlocked
  File "<frozen importlib._bootstrap_external>", line 848, in exec_module
  File "<frozen importlib._bootstrap>", line 219, in _call_with_frames_removed
  File "/home/runner/wws/mysite/urls.py", line 18, in <module>
    import home.views
  File "/home/runner/wws/home/views.py", line 3, in <module>
    from django.backends.base.SessionBase import clear_expired
ModuleNotFoundError: No module named 'django.backends'
[2021-09-06 07:51:35 +0000] [2228] [ERROR] Error handling request /favicon.ico
Traceback (most recent call last):
  File "/opt/virtualenvs/python3/lib/python3.8/site-packages/django/core/handlers/exception.py", line 34, in inner
    response = get_response(request)
  File "/opt/virtualenvs/python3/lib/python3.8/site-packages/django/utils/deprecation.py", line 93, in __call__
    response = self.process_request(request)
  File "/opt/virtualenvs/python3/lib/python3.8/site-packages/django/middleware/common.py", line 53, in process_request
    if self.should_redirect_with_slash(request):
  File "/opt/virtualenvs/python3/lib/python3.8/site-packages/django/middleware/common.py", line 71, in should_redirect_with_slash
    not is_valid_path(request.path_info, urlconf) and
  File "/opt/virtualenvs/python3/lib/python3.8/site-packages/django/urls/base.py", line 154, in is_valid_path
    resolve(path, urlconf)
  File "/opt/virtualenvs/python3/lib/python3.8/site-packages/django/urls/base.py", line 25, in resolve
    return get_resolver(urlconf).resolve(path)
  File "/opt/virtualenvs/python3/lib/python3.8/site-packages/django/urls/resolvers.py", line 544, in resolve
    for pattern in self.url_patterns:
  File "/opt/virtualenvs/python3/lib/python3.8/site-packages/django/utils/functional.py", line 48, in __get__
    res = instance.__dict__[self.name] = self.func(instance)
  File "/opt/virtualenvs/python3/lib/python3.8/site-packages/django/urls/resolvers.py", line 588, in url_patterns
    patterns = getattr(self.urlconf_module, "urlpatterns", self.urlconf_module)
  File "/opt/virtualenvs/python3/lib/python3.8/site-packages/django/utils/functional.py", line 48, in __get__
    res = instance.__dict__[self.name] = self.func(instance)
  File "/opt/virtualenvs/python3/lib/python3.8/site-packages/django/urls/resolvers.py", line 581, in urlconf_module
    return import_module(self.urlconf_name)
  File "/usr/lib/python3.8/importlib/__init__.py", line 127, in import_module
    return _bootstrap._gcd_import(name[level:], package, level)
  File "<frozen importlib._bootstrap>", line 1014, in _gcd_import
  File "<frozen importlib._bootstrap>", line 991, in _find_and_load
  File "<frozen importlib._bootstrap>", line 975, in _find_and_load_unlocked
  File "<frozen importlib._bootstrap>", line 671, in _load_unlocked
  File "<frozen importlib._bootstrap_external>", line 848, in exec_module
  File "<frozen importlib._bootstrap>", line 219, in _call_with_frames_removed
  File "/home/runner/wws/mysite/urls.py", line 18, in <module>
    import home.views
  File "/home/runner/wws/home/views.py", line 3, in <module>
    from django.backends.base.SessionBase import clear_expired
ModuleNotFoundError: No module named 'django.backends'

During handling of the above exception, another exception occurred:

Traceback (most recent call last):
  File "/opt/virtualenvs/python3/lib/python3.8/site-packages/django/core/handlers/exception.py", line 34, in inner
    response = get_response(request)
  File "/opt/virtualenvs/python3/lib/python3.8/site-packages/django/utils/deprecation.py", line 94, in __call__
    response = response or self.get_response(request)
  File "/opt/virtualenvs/python3/lib/python3.8/site-packages/django/core/handlers/exception.py", line 36, in inner
    response = response_for_exception(request, exc)
  File "/opt/virtualenvs/python3/lib/python3.8/site-packages/django/core/handlers/exception.py", line 90, in response_for_exception
    response = handle_uncaught_exception(request, get_resolver(get_urlconf()), sys.exc_info())
  File "/opt/virtualenvs/python3/lib/python3.8/site-packages/django/core/handlers/exception.py", line 128, in handle_uncaught_exception
    callback, param_dict = resolver.resolve_error_handler(500)
  File "/opt/virtualenvs/python3/lib/python3.8/site-packages/django/urls/resolvers.py", line 601, in resolve_error_handler
    callback = getattr(self.urlconf_module, 'handler%s' % view_type, None)
  File "/opt/virtualenvs/python3/lib/python3.8/site-packages/django/utils/functional.py", line 48, in __get__
    res = instance.__dict__[self.name] = self.func(instance)
  File "/opt/virtualenvs/python3/lib/python3.8/site-packages/django/urls/resolvers.py", line 581, in urlconf_module
    return import_module(self.urlconf_name)
  File "/usr/lib/python3.8/importlib/__init__.py", line 127, in import_module
    return _bootstrap._gcd_import(name[level:], package, level)
  File "<frozen importlib._bootstrap>", line 1014, in _gcd_import
  File "<frozen importlib._bootstrap>", line 991, in _find_and_load
  File "<frozen importlib._bootstrap>", line 975, in _find_and_load_unlocked
  File "<frozen importlib._bootstrap>", line 671, in _load_unlocked
  File "<frozen importlib._bootstrap_external>", line 848, in exec_module
  File "<frozen importlib._bootstrap>", line 219, in _call_with_frames_removed
  File "/home/runner/wws/mysite/urls.py", line 18, in <module>
    import home.views
  File "/home/runner/wws/home/views.py", line 3, in <module>
    from django.backends.base.SessionBase import clear_expired
ModuleNotFoundError: No module named 'django.backends'

During handling of the above exception, another exception occurred:

Traceback (most recent call last):
  File "/opt/virtualenvs/python3/lib/python3.8/site-packages/django/core/handlers/exception.py", line 34, in inner
    response = get_response(request)
  File "/opt/virtualenvs/python3/lib/python3.8/site-packages/django/utils/deprecation.py", line 94, in __call__
    response = response or self.get_response(request)
  File "/opt/virtualenvs/python3/lib/python3.8/site-packages/django/core/handlers/exception.py", line 36, in inner
    response = response_for_exception(request, exc)
  File "/opt/virtualenvs/python3/lib/python3.8/site-packages/django/core/handlers/exception.py", line 90, in response_for_exception
    response = handle_uncaught_exception(request, get_resolver(get_urlconf()), sys.exc_info())
  File "/opt/virtualenvs/python3/lib/python3.8/site-packages/django/core/handlers/exception.py", line 128, in handle_uncaught_exception
    callback, param_dict = resolver.resolve_error_handler(500)
  File "/opt/virtualenvs/python3/lib/python3.8/site-packages/django/urls/resolvers.py", line 601, in resolve_error_handler
    callback = getattr(self.urlconf_module, 'handler%s' % view_type, None)
  File "/opt/virtualenvs/python3/lib/python3.8/site-packages/django/utils/functional.py", line 48, in __get__
    res = instance.__dict__[self.name] = self.func(instance)
  File "/opt/virtualenvs/python3/lib/python3.8/site-packages/django/urls/resolvers.py", line 581, in urlconf_module
    return import_module(self.urlconf_name)
  File "/usr/lib/python3.8/importlib/__init__.py", line 127, in import_module
    return _bootstrap._gcd_import(name[level:], package, level)
  File "<frozen importlib._bootstrap>", line 1014, in _gcd_import
  File "<frozen importlib._bootstrap>", line 991, in _find_and_load
  File "<frozen importlib._bootstrap>", line 975, in _find_and_load_unlocked
  File "<frozen importlib._bootstrap>", line 671, in _load_unlocked
  File "<frozen importlib._bootstrap_external>", line 848, in exec_module
  File "<frozen importlib._bootstrap>", line 219, in _call_with_frames_removed
  File "/home/runner/wws/mysite/urls.py", line 18, in <module>
    import home.views
  File "/home/runner/wws/home/views.py", line 3, in <module>
    from django.backends.base.SessionBase import clear_expired
ModuleNotFoundError: No module named 'django.backends'

During handling of the above exception, another exception occurred:

Traceback (most recent call last):
  File "/opt/virtualenvs/python3/lib/python3.8/site-packages/gunicorn/workers/sync.py", line 136, in handle
    self.handle_request(listener, req, client, addr)
  File "/opt/virtualenvs/python3/lib/python3.8/site-packages/gunicorn/workers/sync.py", line 179, in handle_request
    respiter = self.wsgi(environ, resp.start_response)
  File "/opt/virtualenvs/python3/lib/python3.8/site-packages/whitenoise/base.py", line 85, in __call__
    return self.application(environ, start_response)
  File "/opt/virtualenvs/python3/lib/python3.8/site-packages/django/core/handlers/wsgi.py", line 133, in __call__
    response = self.get_response(request)
  File "/opt/virtualenvs/python3/lib/python3.8/site-packages/django/core/handlers/base.py", line 75, in get_response
    response = self._middleware_chain(request)
  File "/opt/virtualenvs/python3/lib/python3.8/site-packages/django/core/handlers/exception.py", line 36, in inner
    response = response_for_exception(request, exc)
  File "/opt/virtualenvs/python3/lib/python3.8/site-packages/django/core/handlers/exception.py", line 90, in response_for_exception
    response = handle_uncaught_exception(request, get_resolver(get_urlconf()), sys.exc_info())
  File "/opt/virtualenvs/python3/lib/python3.8/site-packages/django/core/handlers/exception.py", line 128, in handle_uncaught_exception
    callback, param_dict = resolver.resolve_error_handler(500)
  File "/opt/virtualenvs/python3/lib/python3.8/site-packages/django/urls/resolvers.py", line 601, in resolve_error_handler
    callback = getattr(self.urlconf_module, 'handler%s' % view_type, None)
  File "/opt/virtualenvs/python3/lib/python3.8/site-packages/django/utils/functional.py", line 48, in __get__
    res = instance.__dict__[self.name] = self.func(instance)
  File "/opt/virtualenvs/python3/lib/python3.8/site-packages/django/urls/resolvers.py", line 581, in urlconf_module
    return import_module(self.urlconf_name)
  File "/usr/lib/python3.8/importlib/__init__.py", line 127, in import_module
    return _bootstrap._gcd_import(name[level:], package, level)
  File "<frozen importlib._bootstrap>", line 1014, in _gcd_import
  File "<frozen importlib._bootstrap>", line 991, in _find_and_load
  File "<frozen importlib._bootstrap>", line 975, in _find_and_load_unlocked
  File "<frozen importlib._bootstrap>", line 671, in _load_unlocked
  File "<frozen importlib._bootstrap_external>", line 848, in exec_module
  File "<frozen importlib._bootstrap>", line 219, in _call_with_frames_removed
  File "/home/runner/wws/mysite/urls.py", line 18, in <module>
    import home.views
  File "/home/runner/wws/home/views.py", line 3, in <module>
    from django.backends.base.SessionBase import clear_expired
ModuleNotFoundError: No module named 'django.backends'
[2021-09-06 07:51:48 +0000] [2228] [INFO] Worker exiting (pid: 2228)
[2021-09-06 07:51:48 +0000] [2218] [INFO] Handling signal: term
[2021-09-06 07:51:49 +0000] [2218] [INFO] Shutting down: Master
[2021-09-06 07:51:50 +0000] [2257] [INFO] Starting gunicorn 20.1.0
[2021-09-06 07:51:50 +0000] [2257] [INFO] Listening at: http://0.0.0.0:8080 (2257)
[2021-09-06 07:51:50 +0000] [2257] [INFO] Using worker: sync
[2021-09-06 07:51:50 +0000] [2267] [INFO] Booting worker with pid: 2267
[2021-09-06 10:23:36 +0000] [2257] [INFO] Handling signal: winch
[2021-09-06 10:23:36 +0000] [2257] [INFO] Handling signal: winch
[2021-09-06 10:25:13 +0000] [2267] [INFO] Worker exiting (pid: 2267)
[2021-09-06 10:25:13 +0000] [2257] [INFO] Handling signal: term
[2021-09-06 10:25:13 +0000] [2257] [WARNING] Worker with pid 2267 was terminated due to signal 15
[2021-09-06 10:25:13 +0000] [2257] [INFO] Shutting down: Master
[2021-09-06 10:25:14 +0000] [2317] [INFO] Starting gunicorn 20.1.0
[2021-09-06 10:25:14 +0000] [2317] [INFO] Listening at: http://0.0.0.0:8080 (2317)
[2021-09-06 10:25:14 +0000] [2317] [INFO] Using worker: sync
[2021-09-06 10:25:14 +0000] [2327] [INFO] Booting worker with pid: 2327
[2021-09-06 10:26:03 +0000] [2327] [INFO] Worker exiting (pid: 2327)
[2021-09-06 10:26:03 +0000] [2317] [INFO] Handling signal: term
[2021-09-06 10:26:03 +0000] [2317] [WARNING] Worker with pid 2327 was terminated due to signal 15
[2021-09-06 10:26:03 +0000] [2317] [INFO] Shutting down: Master
[2021-09-06 10:26:04 +0000] [2356] [INFO] Starting gunicorn 20.1.0
[2021-09-06 10:26:04 +0000] [2356] [INFO] Listening at: http://0.0.0.0:8080 (2356)
[2021-09-06 10:26:04 +0000] [2356] [INFO] Using worker: sync
[2021-09-06 10:26:04 +0000] [2366] [INFO] Booting worker with pid: 2366
[2021-09-06 11:30:47 +0000] [2356] [INFO] Handling signal: winch
[2021-09-06 11:36:21 +0000] [2356] [INFO] Handling signal: winch
[2021-09-06 11:36:21 +0000] [2356] [INFO] Handling signal: winch
[2021-09-06 11:40:48 +0000] [2366] [INFO] Worker exiting (pid: 2366)
[2021-09-06 11:40:48 +0000] [2356] [INFO] Handling signal: term
[2021-09-06 11:40:48 +0000] [2356] [INFO] Shutting down: Master
[2021-09-06 11:40:49 +0000] [3128] [INFO] Starting gunicorn 20.1.0
[2021-09-06 11:40:49 +0000] [3128] [INFO] Listening at: http://0.0.0.0:8080 (3128)
[2021-09-06 11:40:49 +0000] [3128] [INFO] Using worker: sync
[2021-09-06 11:40:49 +0000] [3138] [INFO] Booting worker with pid: 3138
[2021-09-06 11:41:06 +0000] [3128] [INFO] Handling signal: term
[2021-09-06 11:41:06 +0000] [3138] [INFO] Worker exiting (pid: 3138)
[2021-09-06 11:41:06 +0000] [3128] [INFO] Shutting down: Master
[2021-09-06 11:41:07 +0000] [3163] [INFO] Starting gunicorn 20.1.0
[2021-09-06 11:41:07 +0000] [3163] [INFO] Listening at: http://0.0.0.0:8080 (3163)
[2021-09-06 11:41:07 +0000] [3163] [INFO] Using worker: sync
[2021-09-06 11:41:07 +0000] [3173] [INFO] Booting worker with pid: 3173
[2021-09-06 12:08:05 +0000] [3163] [INFO] Handling signal: winch
[2021-09-06 12:11:58 +0000] [3173] [INFO] Worker exiting (pid: 3173)
[2021-09-06 12:11:58 +0000] [3163] [INFO] Handling signal: term
[2021-09-06 12:11:58 +0000] [3163] [WARNING] Worker with pid 3173 was terminated due to signal 15
[2021-09-06 12:11:58 +0000] [3163] [INFO] Shutting down: Master
[2021-09-06 12:12:01 +0000] [3723] [INFO] Starting gunicorn 20.1.0
[2021-09-06 12:12:01 +0000] [3723] [INFO] Listening at: http://0.0.0.0:8080 (3723)
[2021-09-06 12:12:01 +0000] [3723] [INFO] Using worker: sync
[2021-09-06 12:12:01 +0000] [3733] [INFO] Booting worker with pid: 3733
[2021-09-06 12:12:41 +0000] [3723] [INFO] Handling signal: term
[2021-09-06 12:12:41 +0000] [3733] [INFO] Worker exiting (pid: 3733)
[2021-09-06 12:12:42 +0000] [3723] [INFO] Shutting down: Master
[2021-09-06 12:12:43 +0000] [3769] [INFO] Starting gunicorn 20.1.0
[2021-09-06 12:12:43 +0000] [3769] [INFO] Listening at: http://0.0.0.0:8080 (3769)
[2021-09-06 12:12:43 +0000] [3769] [INFO] Using worker: sync
[2021-09-06 12:12:43 +0000] [3779] [INFO] Booting worker with pid: 3779
[2021-09-06 12:13:01 +0000] [3779] [INFO] Worker exiting (pid: 3779)
[2021-09-06 12:13:01 +0000] [3769] [INFO] Handling signal: term
[2021-09-06 12:13:01 +0000] [3769] [WARNING] Worker with pid 3779 was terminated due to signal 15
[2021-09-06 12:13:01 +0000] [3769] [INFO] Shutting down: Master
[2021-09-06 12:13:02 +0000] [3808] [INFO] Starting gunicorn 20.1.0
[2021-09-06 12:13:02 +0000] [3808] [INFO] Listening at: http://0.0.0.0:8080 (3808)
[2021-09-06 12:13:02 +0000] [3808] [INFO] Using worker: sync
[2021-09-06 12:13:02 +0000] [3818] [INFO] Booting worker with pid: 3818
[2021-09-06 12:17:04 +0000] [3818] [INFO] Worker exiting (pid: 3818)
[2021-09-06 12:17:04 +0000] [3808] [INFO] Handling signal: term
[2021-09-06 12:17:04 +0000] [3808] [WARNING] Worker with pid 3818 was terminated due to signal 15
[2021-09-06 12:17:04 +0000] [3808] [INFO] Shutting down: Master
